Workbook
Name PRZEL_AKCESORIA: Analiza!$B$4
Name BAZA_SKOK: BAZA!$E$3:$E$202
Name BAZA_PROG: BAZA!$F$3:$F$202
Name LISTA_EX: LISTY!$GV$3:$GV$202
Name BAZA_COEFF: BAZA!$D$3:$D$202
Name BAZA_KAT: BAZA!$B$3:$B$202
Name BAZA_ID: BAZA!$H$3:$H$202
Name LISTA_KLUCZ: LISTY!$GW$3:$GW$202
Name PRZEL_CZESC: Analiza!$B$5
Name BAZA_FILM: BAZA!$G$3:$G$202
Name BAZA_EX: BAZA!$A$3:$A$202
Name BAZA_PART: BAZA!$C$3:$C$202
Name BAZA_UWAGI: BAZA!$I$3:$I$202

Sheet START
A1: PLAN TRENINGOWY — 6 TYGODNI
A2: Start planu treningowego | D2: =IF($C$2="","","→ koniec 6. tygodnia: "&TEXT($C$2+41,"dd.mm.yyyy"))
A3: SERIE MAKSYMALNE — jedna seria do odmowy na każde ćwiczenie
A4: Lp. | B4: ĆWICZENIE | C4: ciężar (kg) | D4: powtórzenia | E4: Twój 1RM
A5: DZIEŃ I
A6: =IF('T1'!$A7="","",'T1'!$A7) -> A1. | B6: =IF('T1'!$C7="","",'T1'!$C7) | E6: {=IF(OR($C6="",$D6=""),"",IFERROR(ROUND($C6/(INDEX(TABELE!$B$4:$J$18,MATCH($D6,TABELE!$A$4:$A$18,0),MATCH(10,TABELE!$B$3:$J$3,0))/100),1),"powt. 1–15"))} | K6: D1-S01 | L6: =IF('T1'!$C7="","",'T1'!$Q7) | M6: =IF(N($E6)=0,0,$E6) -> 0 | N6: =IF($B6="",0,SUMPRODUCT(MAX(($B$6:$B$69=$B6)*$M$6:$M$69))) -> 0
A7: =IF('T1'!$A8="","",'T1'!$A8) -> B1. | B7: =IF('T1'!$C8="","",'T1'!$C8) | C7: 50 | D7: 8 | E7: {=IF(OR($C7="",$D7=""),"",IFERROR(ROUND($C7/(INDEX(TABELE!$B$4:$J$18,MATCH($D7,TABELE!$A$4:$A$18,0),MATCH(10,TABELE!$B$3:$J$3,0))/100),1),"powt. 1–15"))} -> 62.1 | K7: D1-S02 | L7: =IF('T1'!$C8="","",'T1'!$Q8) -> kg | M7: =IF(N($E7)=0,0,$E7) -> 62.1 | N7: =IF($B7="",0,SUMPRODUCT(MAX(($B$6:$B$69=$B7)*$M$6:$M$69))) -> 0
A8: =IF('T1'!$A9="","",'T1'!$A9) -> B2. | B8: =IF('T1'!$C9="","",'T1'!$C9) | E8: {=IF(OR($C8="",$D8=""),"",IFERROR(ROUND($C8/(INDEX(TABELE!$B$4:$J$18,MATCH($D8,TABELE!$A$4:$A$18,0),MATCH(10,TABELE!$B$3:$J$3,0))/100),1),"powt. 1–15"))} | K8: D1-S03 | L8: =IF('T1'!$C9="","",'T1'!$Q9) | M8: =IF(N($E8)=0,0,$E8) -> 0 | N8: =IF($B8="",0,SUMPRODUCT(MAX(($B$6:$B$69=$B8)*$M$6:$M$69))) -> 0
A9: =IF('T1'!$A10="","",'T1'!$A10) -> C1. | B9: =IF('T1'!$C10="","",'T1'!$C10) | E9: {=IF(OR($C9="",$D9=""),"",IFERROR(ROUND($C9/(INDEX(TABELE!$B$4:$J$18,MATCH($D9,TABELE!$A$4:$A$18,0),MATCH(10,TABELE!$B$3:$J$3,0))/100),1),"powt. 1–15"))} | K9: D1-S04 | L9: =IF('T1'!$C10="","",'T1'!$Q10) | M9: =IF(N($E9)=0,0,$E9) -> 0 | N9: =IF($B9="",0,SUMPRODUCT(MAX(($B$6:$B$69=$B9)*$M$6:$M$69))) -> 0
A10: =IF('T1'!$A11="","",'T1'!$A11) -> C2. | B10: =IF('T1'!$C11="","",'T1'!$C11) | E10: {=IF(OR($C10="",$D10=""),"",IFERROR(ROUND($C10/(INDEX(TABELE!$B$4:$J$18,MATCH($D10,TABELE!$A$4:$A$18,0),MATCH(10,TABELE!$B$3:$J$3,0))/100),1),"powt. 1–15"))} | K10: D1-S05 | L10: =IF('T1'!$C11="","",'T1'!$Q11) | M10: =IF(N($E10)=0,0,$E10) -> 0 | N10: =IF($B10="",0,SUMPRODUCT(MAX(($B$6:$B$69=$B10)*$M$6:$M$69))) -> 0
A11: =IF('T1'!$A12="","",'T1'!$A12) -> D1. | B11: =IF('T1'!$C12="","",'T1'!$C12) | E11: {=IF(OR($C11="",$D11=""),"",IFERROR(ROUND($C11/(INDEX(TABELE!$B$4:$J$18,MATCH($D11,TABELE!$A$4:$A$18,0),MATCH(10,TABELE!$B$3:$J$3,0))/100),1),"powt. 1–15"))} | K11: D1-S06 | L11: =IF('T1'!$C12="","",'T1'!$Q12) | M11: =IF(N($E11)=0,0,$E11) -> 0 | N11: =IF($B11="",0,SUMPRODUCT(MAX(($B$6:$B$69=$B11)*$M$6:$M$69))) -> 0
A12: =IF('T1'!$A13="","",'T1'!$A13) -> D2. | B12: =IF('T1'!$C13="","",'T1'!$C13) | E12: {=IF(OR($C12="",$D12=""),"",IFERROR(ROUND($C12/(INDEX(TABELE!$B$4:$J$18,MATCH($D12,TABELE!$A$4:$A$18,0),MATCH(10,TABELE!$B$3:$J$3,0))/100),1),"powt. 1–15"))} | K12: D1-S07 | L12: =IF('T1'!$C13="","",'T1'!$Q13) | M12: =IF(N($E12)=0,0,$E12) -> 0 | N12: =IF($B12="",0,SUMPRODUCT(MAX(($B$6:$B$69=$B12)*$M$6:$M$69))) -> 0
A13: =IF('T1'!$A14="","",'T1'!$A14) -> E1. | B13: =IF('T1'!$C14="","",'T1'!$C14) | E13: {=IF(OR($C13="",$D13=""),"",IFERROR(ROUND($C13/(INDEX(TABELE!$B$4:$J$18,MATCH($D13,TABELE!$A$4:$A$18,0),MATCH(10,TABELE!$B$3:$J$3,0))/100),1),"powt. 1–15"))} | K13: D1-S08 | L13: =IF('T1'!$C14="","",'T1'!$Q14) | M13: =IF(N($E13)=0,0,$E13) -> 0 | N13: =IF($B13="",0,SUMPRODUCT(MAX(($B$6:$B$69=$B13)*$M$6:$M$69))) -> 0
A14: =IF('T1'!$A15="","",'T1'!$A15) -> E2. | B14: =IF('T1'!$C15="","",'T1'!$C15) | E14: {=IF(OR($C14="",$D14=""),"",IFERROR(ROUND($C14/(INDEX(TABELE!$B$4:$J$18,MATCH($D14,TABELE!$A$4:$A$18,0),MATCH(10,TABELE!$B$3:$J$3,0))/100),1),"powt. 1–15"))} | K14: D1-S09 | L14: =IF('T1'!$C15="","",'T1'!$Q15) | M14: =IF(N($E14)=0,0,$E14) -> 0 | N14: =IF($B14="",0,SUMPRODUCT(MAX(($B$6:$B$69=$B14)*$M$6:$M$69))) -> 0
A15: =IF('T1'!$A16="","",'T1'!$A16) | B15: =IF('T1'!$C16="","",'T1'!$C16) | E15: {=IF(OR($C15="",$D15=""),"",IFERROR(ROUND($C15/(INDEX(TABELE!$B$4:$J$18,MATCH($D15,TABELE!$A$4:$A$18,0),MATCH(10,TABELE!$B$3:$J$3,0))/100),1),"powt. 1–15"))} | K15: D1-S10 | L15: =IF('T1'!$C16="","",'T1'!$Q16) | M15: =IF(N($E15)=0,0,$E15) -> 0 | N15: =IF($B15="",0,SUMPRODUCT(MAX(($B$6:$B$69=$B15)*$M$6:$M$69))) -> 0
A16: =IF('T1'!$A17="","",'T1'!$A17) | B16: =IF('T1'!$C17="","",'T1'!$C17) | E16: {=IF(OR($C16="",$D16=""),"",IFERROR(ROUND($C16/(INDEX(TABELE!$B$4:$J$18,MATCH($D16,TABELE!$A$4:$A$18,0),MATCH(10,TABELE!$B$3:$J$3,0))/100),1),"powt. 1–15"))} | K16: D1-S11 | L16: =IF('T1'!$C17="","",'T1'!$Q17) | M16: =IF(N($E16)=0,0,$E16) -> 0 | N16: =IF($B16="",0,SUMPRODUCT(MAX(($B$6:$B$69=$B16)*$M$6:$M$69))) -> 0
A17: =IF('T1'!$A18="","",'T1'!$A18) | B17: =IF('T1'!$C18="","",'T1'!$C18) | E17: {=IF(OR($C17="",$D17=""),"",IFERROR(ROUND($C17/(INDEX(TABELE!$B$4:$J$18,MATCH($D17,TABELE!$A$4:$A$18,0),MATCH(10,TABELE!$B$3:$J$3,0))/100),1),"powt. 1–15"))} | K17: D1-S12 | L17: =IF('T1'!$C18="","",'T1'!$Q18) | M17: =IF(N($E17)=0,0,$E17) -> 0 | N17: =IF($B17="",0,SUMPRODUCT(MAX(($B$6:$B$69=$B17)*$M$6:$M$69))) -> 0
A18: DZIEŃ II | M18: =IF(N($E18)=0,0,$E18) -> 0 | N18: =IF($B18="",0,SUMPRODUCT(MAX(($B$6:$B$69=$B18)*$M$6:$M$69))) -> 0
A19: =IF('T1'!$A23="","",'T1'!$A23) -> A1. | B19: =IF('T1'!$C23="","",'T1'!$C23) | E19: {=IF(OR($C19="",$D19=""),"",IFERROR(ROUND($C19/(INDEX(TABELE!$B$4:$J$18,MATCH($D19,TABELE!$A$4:$A$18,0),MATCH(10,TABELE!$B$3:$J$3,0))/100),1),"powt. 1–15"))} | K19: D2-S01 | L19: =IF('T1'!$C23="","",'T1'!$Q23) | M19: =IF(N($E19)=0,0,$E19) -> 0 | N19: =IF($B19="",0,SUMPRODUCT(MAX(($B$6:$B$69=$B19)*$M$6:$M$69))) -> 0
A20: =IF('T1'!$A24="","",'T1'!$A24) -> B1. | B20: =IF('T1'!$C24="","",'T1'!$C24) | E20: {=IF(OR($C20="",$D20=""),"",IFERROR(ROUND($C20/(INDEX(TABELE!$B$4:$J$18,MATCH($D20,TABELE!$A$4:$A$18,0),MATCH(10,TABELE!$B$3:$J$3,0))/100),1),"powt. 1–15"))} | K20: D2-S02 | L20: =IF('T1'!$C24="","",'T1'!$Q24) | M20: =IF(N($E20)=0,0,$E20) -> 0 | N20: =IF($B20="",0,SUMPRODUCT(MAX(($B$6:$B$69=$B20)*$M$6:$M$69))) -> 0
A21: =IF('T1'!$A25="","",'T1'!$A25) -> B2. | B21: =IF('T1'!$C25="","",'T1'!$C25) | E21: {=IF(OR($C21="",$D21=""),"",IFERROR(ROUND($C21/(INDEX(TABELE!$B$4:$J$18,MATCH($D21,TABELE!$A$4:$A$18,0),MATCH(10,TABELE!$B$3:$J$3,0))/100),1),"powt. 1–15"))} | K21: D2-S03 | L21: =IF('T1'!$C25="","",'T1'!$Q25) | M21: =IF(N($E21)=0,0,$E21) -> 0 | N21: =IF($B21="",0,SUMPRODUCT(MAX(($B$6:$B$69=$B21)*$M$6:$M$69))) -> 0
A22: =IF('T1'!$A26="","",'T1'!$A26) -> C1. | B22: =IF('T1'!$C26="","",'T1'!$C26) | E22: {=IF(OR($C22="",$D22=""),"",IFERROR(ROUND($C22/(INDEX(TABELE!$B$4:$J$18,MATCH($D22,TABELE!$A$4:$A$18,0),MATCH(10,TABELE!$B$3:$J$3,0))/100),1),"powt. 1–15"))} | K22: D2-S04 | L22: =IF('T1'!$C26="","",'T1'!$Q26) | M22: =IF(N($E22)=0,0,$E22) -> 0 | N22: =IF($B22="",0,SUMPRODUCT(MAX(($B$6:$B$69=$B22)*$M$6:$M$69))) -> 0
A23: =IF('T1'!$A27="","",'T1'!$A27) -> C2. | B23: =IF('T1'!$C27="","",'T1'!$C27) | E23: {=IF(OR($C23="",$D23=""),"",IFERROR(ROUND($C23/(INDEX(TABELE!$B$4:$J$18,MATCH($D23,TABELE!$A$4:$A$18,0),MATCH(10,TABELE!$B$3:$J$3,0))/100),1),"powt. 1–15"))} | K23: D2-S05 | L23: =IF('T1'!$C27="","",'T1'!$Q27) | M23: =IF(N($E23)=0,0,$E23) -> 0 | N23: =IF($B23="",0,SUMPRODUCT(MAX(($B$6:$B$69=$B23)*$M$6:$M$69))) -> 0
A24: =IF('T1'!$A28="","",'T1'!$A28) -> D1. | B24: =IF('T1'!$C28="","",'T1'!$C28) | E24: {=IF(OR($C24="",$D24=""),"",IFERROR(ROUND($C24/(INDEX(TABELE!$B$4:$J$18,MATCH($D24,TABELE!$A$4:$A$18,0),MATCH(10,TABELE!$B$3:$J$3,0))/100),1),"powt. 1–15"))} | K24: D2-S06 | L24: =IF('T1'!$C28="","",'T1'!$Q28) | M24: =IF(N($E24)=0,0,$E24) -> 0 | N24: =IF($B24="",0,SUMPRODUCT(MAX(($B$6:$B$69=$B24)*$M$6:$M$69))) -> 0
A25: =IF('T1'!$A29="","",'T1'!$A29) -> D2. | B25: =IF('T1'!$C29="","",'T1'!$C29) | E25: {=IF(OR($C25="",$D25=""),"",IFERROR(ROUND($C25/(INDEX(TABELE!$B$4:$J$18,MATCH($D25,TABELE!$A$4:$A$18,0),MATCH(10,TABELE!$B$3:$J$3,0))/100),1),"powt. 1–15"))} | K25: D2-S07 | L25: =IF('T1'!$C29="","",'T1'!$Q29) | M25: =IF(N($E25)=0,0,$E25) -> 0 | N25: =IF($B25="",0,SUMPRODUCT(MAX(($B$6:$B$69=$B25)*$M$6:$M$69))) -> 0
A26: =IF('T1'!$A30="","",'T1'!$A30) -> E1. | B26: =IF('T1'!$C30="","",'T1'!$C30) | E26: {=IF(OR($C26="",$D26=""),"",IFERROR(ROUND($C26/(INDEX(TABELE!$B$4:$J$18,MATCH($D26,TABELE!$A$4:$A$18,0),MATCH(10,TABELE!$B$3:$J$3,0))/100),1),"powt. 1–15"))} | K26: D2-S08 | L26: =IF('T1'!$C30="","",'T1'!$Q30) | M26: =IF(N($E26)=0,0,$E26) -> 0 | N26: =IF($B26="",0,SUMPRODUCT(MAX(($B$6:$B$69=$B26)*$M$6:$M$69))) -> 0
A27: =IF('T1'!$A31="","",'T1'!$A31) -> E2. | B27: =IF('T1'!$C31="","",'T1'!$C31) | E27: {=IF(OR($C27="",$D27=""),"",IFERROR(ROUND($C27/(INDEX(TABELE!$B$4:$J$18,MATCH($D27,TABELE!$A$4:$A$18,0),MATCH(10,TABELE!$B$3:$J$3,0))/100),1),"powt. 1–15"))} | K27: D2-S09 | L27: =IF('T1'!$C31="","",'T1'!$Q31) | M27: =IF(N($E27)=0,0,$E27) -> 0 | N27: =IF($B27="",0,SUMPRODUCT(MAX(($B$6:$B$69=$B27)*$M$6:$M$69))) -> 0
A28: =IF('T1'!$A32="","",'T1'!$A32) | B28: =IF('T1'!$C32="","",'T1'!$C32) | E28: {=IF(OR($C28="",$D28=""),"",IFERROR(ROUND($C28/(INDEX(TABELE!$B$4:$J$18,MATCH($D28,TABELE!$A$4:$A$18,0),MATCH(10,TABELE!$B$3:$J$3,0))/100),1),"powt. 1–15"))} | K28: D2-S10 | L28: =IF('T1'!$C32="","",'T1'!$Q32) | M28: =IF(N($E28)=0,0,$E28) -> 0 | N28: =IF($B28="",0,SUMPRODUCT(MAX(($B$6:$B$69=$B28)*$M$6:$M$69))) -> 0
A29: =IF('T1'!$A33="","",'T1'!$A33) | B29: =IF('T1'!$C33="","",'T1'!$C33) | E29: {=IF(OR($C29="",$D29=""),"",IFERROR(ROUND($C29/(INDEX(TABELE!$B$4:$J$18,MATCH($D29,TABELE!$A$4:$A$18,0),MATCH(10,TABELE!$B$3:$J$3,0))/100),1),"powt. 1–15"))} | K29: D2-S11 | L29: =IF('T1'!$C33="","",'T1'!$Q33) | M29: =IF(N($E29)=0,0,$E29) -> 0 | N29: =IF($B29="",0,SUMPRODUCT(MAX(($B$6:$B$69=$B29)*$M$6:$M$69))) -> 0
A30: =IF('T1'!$A34="","",'T1'!$A34) | B30: =IF('T1'!$C34="","",'T1'!$C34) | E30: {=IF(OR($C30="",$D30=""),"",IFERROR(ROUND($C30/(INDEX(TABELE!$B$4:$J$18,MATCH($D30,TABELE!$A$4:$A$18,0),MATCH(10,TABELE!$B$3:$J$3,0))/100),1),"powt. 1–15"))} | K30: D2-S12 | L30: =IF('T1'!$C34="","",'T1'!$Q34) | M30: =IF(N($E30)=0,0,$E30) -> 0 | N30: =IF($B30="",0,SUMPRODUCT(MAX(($B$6:$B$69=$B30)*$M$6:$M$69))) -> 0
A31: DZIEŃ III | M31: =IF(N($E31)=0,0,$E31) -> 0 | N31: =IF($B31="",0,SUMPRODUCT(MAX(($B$6:$B$69=$B31)*$M$6:$M$69))) -> 0
A32: =IF('T1'!$A39="","",'T1'!$A39) -> A1. | B32: =IF('T1'!$C39="","",'T1'!$C39) | E32: {=IF(OR($C32="",$D32=""),"",IFERROR(ROUND($C32/(INDEX(TABELE!$B$4:$J$18,MATCH($D32,TABELE!$A$4:$A$18,0),MATCH(10,TABELE!$B$3:$J$3,0))/100),1),"powt. 1–15"))} | K32: D3-S01 | L32: =IF('T1'!$C39="","",'T1'!$Q39) | M32: =IF(N($E32)=0,0,$E32) -> 0 | N32: =IF($B32="",0,SUMPRODUCT(MAX(($B$6:$B$69=$B32)*$M$6:$M$69))) -> 0
A33: =IF('T1'!$A40="","",'T1'!$A40) -> B1. | B33: =IF('T1'!$C40="","",'T1'!$C40) | E33: {=IF(OR($C33="",$D33=""),"",IFERROR(ROUND($C33/(INDEX(TABELE!$B$4:$J$18,MATCH($D33,TABELE!$A$4:$A$18,0),MATCH(10,TABELE!$B$3:$J$3,0))/100),1),"powt. 1–15"))} | K33: D3-S02 | L33: =IF('T1'!$C40="","",'T1'!$Q40) | M33: =IF(N($E33)=0,0,$E33) -> 0 | N33: =IF($B33="",0,SUMPRODUCT(MAX(($B$6:$B$69=$B33)*$M$6:$M$69))) -> 0
A34: =IF('T1'!$A41="","",'T1'!$A41) -> B2. | B34: =IF('T1'!$C41="","",'T1'!$C41) | E34: {=IF(OR($C34="",$D34=""),"",IFERROR(ROUND($C34/(INDEX(TABELE!$B$4:$J$18,MATCH($D34,TABELE!$A$4:$A$18,0),MATCH(10,TABELE!$B$3:$J$3,0))/100),1),"powt. 1–15"))} | K34: D3-S03 | L34: =IF('T1'!$C41="","",'T1'!$Q41) | M34: =IF(N($E34)=0,0,$E34) -> 0 | N34: =IF($B34="",0,SUMPRODUCT(MAX(($B$6:$B$69=$B34)*$M$6:$M$69))) -> 0
A35: =IF('T1'!$A42="","",'T1'!$A42) -> C1. | B35: =IF('T1'!$C42="","",'T1'!$C42) | E35: {=IF(OR($C35="",$D35=""),"",IFERROR(ROUND($C35/(INDEX(TABELE!$B$4:$J$18,MATCH($D35,TABELE!$A$4:$A$18,0),MATCH(10,TABELE!$B$3:$J$3,0))/100),1),"powt. 1–15"))} | K35: D3-S04 | L35: =IF('T1'!$C42="","",'T1'!$Q42) | M35: =IF(N($E35)=0,0,$E35) -> 0 | N35: =IF($B35="",0,SUMPRODUCT(MAX(($B$6:$B$69=$B35)*$M$6:$M$69))) -> 0
A36: =IF('T1'!$A43="","",'T1'!$A43) -> C2. | B36: =IF('T1'!$C43="","",'T1'!$C43) | E36: {=IF(OR($C36="",$D36=""),"",IFERROR(ROUND($C36/(INDEX(TABELE!$B$4:$J$18,MATCH($D36,TABELE!$A$4:$A$18,0),MATCH(10,TABELE!$B$3:$J$3,0))/100),1),"powt. 1–15"))} | K36: D3-S05 | L36: =IF('T1'!$C43="","",'T1'!$Q43) | M36: =IF(N($E36)=0,0,$E36) -> 0 | N36: =IF($B36="",0,SUMPRODUCT(MAX(($B$6:$B$69=$B36)*$M$6:$M$69))) -> 0
A37: =IF('T1'!$A44="","",'T1'!$A44) -> D1. | B37: =IF('T1'!$C44="","",'T1'!$C44) | E37: {=IF(OR($C37="",$D37=""),"",IFERROR(ROUND($C37/(INDEX(TABELE!$B$4:$J$18,MATCH($D37,TABELE!$A$4:$A$18,0),MATCH(10,TABELE!$B$3:$J$3,0))/100),1),"powt. 1–15"))} | K37: D3-S06 | L37: =IF('T1'!$C44="","",'T1'!$Q44) | M37: =IF(N($E37)=0,0,$E37) -> 0 | N37: =IF($B37="",0,SUMPRODUCT(MAX(($B$6:$B$69=$B37)*$M$6:$M$69))) -> 0
A38: =IF('T1'!$A45="","",'T1'!$A45) -> D2. | B38: =IF('T1'!$C45="","",'T1'!$C45) | E38: {=IF(OR($C38="",$D38=""),"",IFERROR(ROUND($C38/(INDEX(TABELE!$B$4:$J$18,MATCH($D38,TABELE!$A$4:$A$18,0),MATCH(10,TABELE!$B$3:$J$3,0))/100),1),"powt. 1–15"))} | K38: D3-S07 | L38: =IF('T1'!$C45="","",'T1'!$Q45) | M38: =IF(N($E38)=0,0,$E38) -> 0 | N38: =IF($B38="",0,SUMPRODUCT(MAX(($B$6:$B$69=$B38)*$M$6:$M$69))) -> 0
A39: =IF('T1'!$A46="","",'T1'!$A46) -> E1. | B39: =IF('T1'!$C46="","",'T1'!$C46) | E39: {=IF(OR($C39="",$D39=""),"",IFERROR(ROUND($C39/(INDEX(TABELE!$B$4:$J$18,MATCH($D39,TABELE!$A$4:$A$18,0),MATCH(10,TABELE!$B$3:$J$3,0))/100),1),"powt. 1–15"))} | K39: D3-S08 | L39: =IF('T1'!$C46="","",'T1'!$Q46) | M39: =IF(N($E39)=0,0,$E39) -> 0 | N39: =IF($B39="",0,SUMPRODUCT(MAX(($B$6:$B$69=$B39)*$M$6:$M$69))) -> 0
A40: =IF('T1'!$A47="","",'T1'!$A47) -> E2. | B40: =IF('T1'!$C47="","",'T1'!$C47) | E40: {=IF(OR($C40="",$D40=""),"",IFERROR(ROUND($C40/(INDEX(TABELE!$B$4:$J$18,MATCH($D40,TABELE!$A$4:$A$18,0),MATCH(10,TABELE!$B$3:$J$3,0))/100),1),"powt. 1–15"))} | K40: D3-S09 | L40: =IF('T1'!$C47="","",'T1'!$Q47) | M40: =IF(N($E40)=0,0,$E40) -> 0 | N40: =IF($B40="",0,SUMPRODUCT(MAX(($B$6:$B$69=$B40)*$M$6:$M$69))) -> 0
...

Sheet INSTRUKCJA
A1: JAK KORZYSTAĆ Z PLANU
A3: OD CZEGO ZACZĄĆ
A4: • | B4: Otwórz zakładkę START. Jest tam lista wszystkich ćwiczeń z planu.
A5: • | B5: Do każdego ćwiczenia z żółtymi polami zrób jedną serię do odmowy — z ciężarem, przy którym nie zrobisz już ani jednego powtórzenia więcej. Powinno to wypaść między 1 a 15 powtórzeniem.
A6: • | B6: Wpisz użyty ciężar i liczbę wykonanych powtórzeń. Kolumna „Twój 1RM” wyliczy się sama.
A7: • | B7: Ćwiczenia wypisane szarą kursywą pomijasz — wykonuje się je na masie ciała, na czas albo na dystans, więc nie potrzebują pomiaru.
A8: • | B8: To robisz raz, na początku. Potem już nic nie liczysz.
A10: JAK CZYTAĆ PLAN
A11: • | B11: Zakładki T1–T6 to kolejne tygodnie. Zaczynasz od T1 i idziesz po kolei.
A12: • | B12: Dni treningowe w tygodniu są opisane jako DZIEŃ I, DZIEŃ II i tak dalej. Wykonuj je w tej kolejności, w której są wypisane.
A13: • | B13: Kolumna SERIE mówi, ile serii masz wykonać. Kolumna POWTÓRZENIA — ile powtórzeń w każdej z nich. Zapis 3 i 10 znaczy trzy serie po dziesięć powtórzeń.
A14: • | B14: Kolumna CIĘŻAR to jedyna liczba, którą ustawiasz na sztandze lub maszynie. Jest już policzona z Twojego wyniku.
A15: • | B15: Jeśli w kolumnie CIĘŻAR widzisz „brak 1RM”, to znaczy, że nie uzupełniłeś serii maksymalnej dla tego ćwiczenia na zakładce START.
A16: • | B16: Kolumna FILM prowadzi do nagrania z techniką. Obejrzyj przed pierwszym powtórzeniem nowego ćwiczenia.
A17: • | B17: Odhacz ✓, kiedy skończysz ćwiczenie.
A19: TOP SET
A20: • | B20: Jeśli w Twoim planie występuje ciemny pasek z trójkątem ▲ na początku dnia — to jedna ciężka próba na jedno powtórzenie. Nie każdy plan i nie każdy dzień go ma.
A21: • | B21: Wykonujesz ją PRZED seriami roboczymi tego samego ćwiczenia, po rozgrzewce.
A22: • | B22: Nie pomijaj jej i nie przenoś na koniec — reszta dnia jest do niej dopasowana.
A23: • | B23: Jedno powtórzenie, jedna próba. Nie powtarzaj jej kilka razy.
A25: SERIE ŁĄCZONE
A26: • | B26: Ćwiczenia oznaczone tą samą literą tworzą parę lub trójkę i mają wspólne tło.
A27: • | B27: Wykonujesz je naprzemiennie: jedna seria pierwszego, od razu jedna seria drugiego, dopiero potem przerwa. I tak do wyczerpania serii.
A28: • | B28: Ćwiczenie z inną literą to nowa grupa — kończysz poprzednią w całości, zanim ją zaczniesz.
A29: • | B29: Ćwiczenie stojące samotnie pod swoją literą robisz normalnie, seria po serii.
A31: PRZERWY I TEMPO
A32: • | B32: Po serii ciężkiej z początku dnia odpoczywaj tyle, ile potrzebujesz, żeby kolejna wyszła technicznie — zwykle 3–5 minut.
A33: • | B33: Między grupami ćwiczeń dodatkowych zwykle wystarcza 1,5–2 minuty.
A34: • | B34: Ruch prowadź kontrolnie w fazie opuszczania. Nie zrzucaj ciężaru.
A36: CZEGO NIE ZMIENIAĆ
A37: • | B37: Nie zwiększaj ciężaru na własną rękę, nawet jeśli seria wyszła lekko. Plan zakłada, że tygodnie 1 i 2 mają być łatwiejsze.
A38: • | B38: Nie dokładaj serii ani ćwiczeń.
A39: • | B39: Kolumna RPE służy do obliczeń i nie musisz się nią kierować podczas treningu.
A40: • | B40: Jeśli ćwiczenie boli — nie „rozćwiczaj” bólu. Przerwij je i zgłoś to, zanim wrócisz do tego ruchu.
A41: • | B41: Jeżeli opuścisz trening, wykonaj go w innym dniu zamiast łączyć dwa dni w jeden.
A42: • | B42: Plan zawiera też liczby techniczne — RPE, wskaźniki obciążenia, podsumowania serii i powtórzeń. Służą mnie do układania i kontroli planu. Ty patrzysz na ćwiczenie, serie, powtórzenia i ciężar.

Sheet T1
A1: TYDZIEŃ 1 z 6
A4: Lp. | C4: ĆWICZENIE | D4: SERIE | E4: POWTÓRZENIA | F4: RPE | G4: CIĘŻAR | H4: ✓ | I4: FILM | J4: KATEGORIE – SZKIELET
A5: DZIEŃ I
A6: =IF($B6="TOP SET","▲","") -> ▲ | B6: TOP SET | C6: =IF(OR($B6<>"TOP SET",$F6=""),"",IF(N($K6)=0,"",IF(INDEX($C$7:$C$18,$K6)="","",INDEX($C$7:$C$18,$K6)))) | D6: =IF(AND($B6="TOP SET",$F6<>""),1,"") | E6: =IF(AND($B6="TOP SET",$F6<>""),"1 powtórzenie","") | F6: 7 | G6: {=IF($B6<>"TOP SET","",IF($C6="","",IF(OR($Q6="masa ciała",$Q6="czas",$Q6="dystans",$Q6="ręczne ustawienie"),"—",IF(OR($R6="",$R6=0),"— brak 1RM",MROUND($R6*IFERROR(INDEX(TABELE!$B$4:$J$18,MATCH(1,TABELE!$A$4:$A$18,0),MATCH($F6,TABELE!$B$3:$J$3,0)),0)/100,MAX($P6,0.5))))))} | K6: =IFERROR(MATCH("A*",$A$7:$A$18,0),0) | P6: =IF(N($K6)=0,"",INDEX($P$7:$P$18,$K6)) | Q6: =IF(N($K6)=0,"",INDEX($Q$7:$Q$18,$K6)) | R6: =IF(N($K6)=0,"",INDEX($R$7:$R$18,$K6))
A7: A1. | D7: 6 | E7: 6 | F7: 6.5 | G7: =IF($C7="","",IF(OR($Q7="masa ciała",$Q7="czas",$Q7="dystans",$Q7="ręczne ustawienie"),$Q7,IF(OR($R7="",$R7=0),"— brak 1RM",MROUND($R7*$S7/100,MAX($P7,0.5))))) | I7: {=IFERROR(IF(IFERROR(INDEX(BAZA_FILM,MATCH($C7,BAZA_EX,0)),"")="","",HYPERLINK(IFERROR(INDEX(BAZA_FILM,MATCH($C7,BAZA_EX,0)),""),"film")),"")} | K7: D1-S01 | L7: {=IFERROR(INDEX(BAZA_ID,MATCH($C7,BAZA_EX,0)),"")} | M7: {=IFERROR(INDEX(BAZA_PART,MATCH($C7,BAZA_EX,0)),"")} | N7: {=IFERROR(INDEX(BAZA_KAT,MATCH($C7,BAZA_EX,0)),"")} | O7: {=IFERROR(INDEX(BAZA_COEFF,MATCH($C7,BAZA_EX,0)),"")} | P7: {=IFERROR(INDEX(BAZA_SKOK,MATCH($C7,BAZA_EX,0)),"")} | Q7: {=IFERROR(INDEX(BAZA_PROG,MATCH($C7,BAZA_EX,0)),"")} | R7: =IF($C7="","",IF(SUMPRODUCT((START!$B$6:$B$69=$C7)*(START!$M$6:$M$69>0))=0,"",SUMPRODUCT(MAX((START!$B$6:$B$69=$C7)*START!$M$6:$M$69)))) | S7: {=IFERROR(INDEX(TABELE!$B$4:$J$18,MATCH($E7,TABELE!$A$4:$A$18,0),MATCH($F7,TABELE!$B$3:$J$3,0)),"")} -> 69.5 | T7: {=IFERROR(IF($C7="",0,$O7*$D7*INDEX(TABELE!$B$23:$P$33,MATCH($F7,TABELE!$A$23:$A$33,0),MATCH($E7,TABELE!$B$22:$P$22,0))),0)} -> 0 | U7: {=IFERROR(IF($C7="",0,$O7*$D7*INDEX(TABELE!$B$37:$P$47,MATCH($F7,TABELE!$A$37:$A$47,0),MATCH($E7,TABELE!$B$36:$P$36,0))),0)} -> 0 | V7: {=IFERROR(IF($C7="",0,$O7*$D7*INDEX(TABELE!$B$51:$P$61,MATCH($F7,TABELE!$A$51:$A$61,0),MATCH($E7,TABELE!$B$50:$P$50,0))),0)} -> 0 | W7: {=IFERROR(INDEX(BAZA_UWAGI,MATCH($C7,BAZA_EX,0)),"")} | X7: =IF($A7="","",$Z7) -> 1 | Y7: =IF($A7="","",LEFT($A7,1)) -> A | Z7: =IF($A7="",0,1) -> 1 | AB7: =IF($C7="","",IF($H7<>"",$H7,IF($H$19="✓ ukończony","OK",""))) | AC7: 1 | AD7: =IF(OR($Q7="masa ciała",$Q7="czas",$Q7="dystans",$Q7="ręczne ustawienie"),MAX(-3,MIN(3,ROUND(($AC7-1)/0.05,0))),0) -> 0
A8: B1. | C8: Allah | D8: 3 | E8: =IF($C8="",0,MIN(15,MAX(1,IF(N($O8)>=1,6,IF(N($O8)>=0.75,IF(PRZEL_CZESC="część 1 (objętość)",8,6),IF(PRZEL_CZESC="część 1 (objętość)",10,8)))+0+$AD8))) -> 10 | F8: 8 | G8: =IF($C8="","",IF(OR($Q8="masa ciała",$Q8="czas",$Q8="dystans",$Q8="ręczne ustawienie"),$Q8,IF(OR($R8="",$R8=0),"— brak 1RM",MROUND($R8*$S8/100,MAX($P8,0.5))))) | I8: {=IFERROR(IF(IFERROR(INDEX(BAZA_FILM,MATCH($C8,BAZA_EX,0)),"")="","",HYPERLINK(IFERROR(INDEX(BAZA_FILM,MATCH($C8,BAZA_EX,0)),""),"film")),"")} -> film | K8: D1-S02 | L8: {=IFERROR(INDEX(BAZA_ID,MATCH($C8,BAZA_EX,0)),"")} -> EX-0003 | M8: {=IFERROR(INDEX(BAZA_PART,MATCH($C8,BAZA_EX,0)),"")} -> c | N8: {=IFERROR(INDEX(BAZA_KAT,MATCH($C8,BAZA_EX,0)),"")} -> Core | O8: {=IFERROR(INDEX(BAZA_COEFF,MATCH($C8,BAZA_EX,0)),"")} -> 0.5 | P8: {=IFERROR(INDEX(BAZA_SKOK,MATCH($C8,BAZA_EX,0)),"")} -> 2.5 | Q8: {=IFERROR(INDEX(BAZA_PROG,MATCH($C8,BAZA_EX,0)),"")} -> kg | R8: =IF($C8="","",IF(SUMPRODUCT((START!$B$6:$B$69=$C8)*(START!$M$6:$M$69>0))=0,"",SUMPRODUCT(MAX((START!$B$6:$B$69=$C8)*START!$M$6:$M$69)))) | S8: {=IFERROR(INDEX(TABELE!$B$4:$J$18,MATCH($E8,TABELE!$A$4:$A$18,0),MATCH($F8,TABELE!$B$3:$J$3,0)),"")} -> 67.5 | T8: {=IFERROR(IF($C8="",0,$O8*$D8*INDEX(TABELE!$B$23:$P$33,MATCH($F8,TABELE!$A$23:$A$33,0),MATCH($E8,TABELE!$B$22:$P$22,0))),0)} -> 1.05 | U8: {=IFERROR(IF($C8="",0,$O8*$D8*INDEX(TABELE!$B$37:$P$47,MATCH($F8,TABELE!$A$37:$A$47,0),MATCH($E8,TABELE!$B$36:$P$36,0))),0)} -> 0.6 | V8: {=IFERROR(IF($C8="",0,$O8*$D8*INDEX(TABELE!$B$51:$P$61,MATCH($F8,TABELE!$A$51:$A$61,0),MATCH($E8,TABELE!$B$50:$P$50,0))),0)} -> 1.65 | W8: {=IFERROR(INDEX(BAZA_UWAGI,MATCH($C8,BAZA_EX,0)),"")} | X8: =IF($A8="","",$Z8) -> 2 | Y8: =IF($A8="",$Y7,LEFT($A8,1)) -> B | Z8: =IF($A8="",$Z7,IF(LEFT($A8,1)=$Y7,$Z7,$Z7+1)) -> 2 | AB8: =IF($C8="","",IF($H8<>"",$H8,IF($H$19="✓ ukończony","OK",""))) | AC8: 1 | AD8: =IF(OR($Q8="masa ciała",$Q8="czas",$Q8="dystans",$Q8="ręczne ustawienie"),MAX(-3,MIN(3,ROUND(($AC8-1)/0.05,0))),0) -> 0
A9: B2. | D9: 3 | E9: =IF($C9="",0,MIN(15,MAX(1,IF(N($O9)>=1,6,IF(N($O9)>=0.75,IF(PRZEL_CZESC="część 1 (objętość)",8,6),IF(PRZEL_CZESC="część 1 (objętość)",10,8)))+0+$AD9))) -> 0 | F9: 8 | G9: =IF($C9="","",IF(OR($Q9="masa ciała",$Q9="czas",$Q9="dystans",$Q9="ręczne ustawienie"),$Q9,IF(OR($R9="",$R9=0),"— brak 1RM",MROUND($R9*$S9/100,MAX($P9,0.5))))) | I9: {=IFERROR(IF(IFERROR(INDEX(BAZA_FILM,MATCH($C9,BAZA_EX,0)),"")="","",HYPERLINK(IFERROR(INDEX(BAZA_FILM,MATCH($C9,BAZA_EX,0)),""),"film")),"")} | K9: D1-S03 | L9: {=IFERROR(INDEX(BAZA_ID,MATCH($C9,BAZA_EX,0)),"")} | M9: {=IFERROR(INDEX(BAZA_PART,MATCH($C9,BAZA_EX,0)),"")} | N9: {=IFERROR(INDEX(BAZA_KAT,MATCH($C9,BAZA_EX,0)),"")} | O9: {=IFERROR(INDEX(BAZA_COEFF,MATCH($C9,BAZA_EX,0)),"")} | P9: {=IFERROR(INDEX(BAZA_SKOK,MATCH($C9,BAZA_EX,0)),"")} | Q9: {=IFERROR(INDEX(BAZA_PROG,MATCH($C9,BAZA_EX,0)),"")} | R9: =IF($C9="","",IF(SUMPRODUCT((START!$B$6:$B$69=$C9)*(START!$M$6:$M$69>0))=0,"",SUMPRODUCT(MAX((START!$B$6:$B$69=$C9)*START!$M$6:$M$69)))) | S9: {=IFERROR(INDEX(TABELE!$B$4:$J$18,MATCH($E9,TABELE!$A$4:$A$18,0),MATCH($F9,TABELE!$B$3:$J$3,0)),"")} | T9: {=IFERROR(IF($C9="",0,$O9*$D9*INDEX(TABELE!$B$23:$P$33,MATCH($F9,TABELE!$A$23:$A$33,0),MATCH($E9,TABELE!$B$22:$P$22,0))),0)} -> 0 | U9: {=IFERROR(IF($C9="",0,$O9*$D9*INDEX(TABELE!$B$37:$P$47,MATCH($F9,TABELE!$A$37:$A$47,0),MATCH($E9,TABELE!$B$36:$P$36,0))),0)} -> 0 | V9: {=IFERROR(IF($C9="",0,$O9*$D9*INDEX(TABELE!$B$51:$P$61,MATCH($F9,TABELE!$A$51:$A$61,0),MATCH($E9,TABELE!$B$50:$P$50,0))),0)} -> 0 | W9: {=IFERROR(INDEX(BAZA_UWAGI,MATCH($C9,BAZA_EX,0)),"")} | X9: =IF($A9="","",$Z9) -> 2 | Y9: =IF($A9="",$Y8,LEFT($A9,1)) -> B | Z9: =IF($A9="",$Z8,IF(LEFT($A9,1)=$Y8,$Z8,$Z8+1)) -> 2 | AB9: =IF($C9="","",IF($H9<>"",$H9,IF($H$19="✓ ukończony","OK",""))) | AC9: 1 | AD9: =IF(OR($Q9="masa ciała",$Q9="czas",$Q9="dystans",$Q9="ręczne ustawienie"),MAX(-3,MIN(3,ROUND(($AC9-1)/0.05,0))),0) -> 0
A10: C1. | D10: 3 | E10: =IF($C10="",0,MIN(15,MAX(1,IF(N($O10)>=1,6,IF(N($O10)>=0.75,IF(PRZEL_CZESC="część 1 (objętość)",8,6),IF(PRZEL_CZESC="część 1 (objętość)",10,8)))+0+$AD10))) -> 0 | F10: 8 | G10: =IF($C10="","",IF(OR($Q10="masa ciała",$Q10="czas",$Q10="dystans",$Q10="ręczne ustawienie"),$Q10,IF(OR($R10="",$R10=0),"— brak 1RM",MROUND($R10*$S10/100,MAX($P10,0.5))))) | I10: {=IFERROR(IF(IFERROR(INDEX(BAZA_FILM,MATCH($C10,BAZA_EX,0)),"")="","",HYPERLINK(IFERROR(INDEX(BAZA_FILM,MATCH($C10,BAZA_EX,0)),""),"film")),"")} | K10: D1-S04 | L10: {=IFERROR(INDEX(BAZA_ID,MATCH($C10,BAZA_EX,0)),"")} | M10: {=IFERROR(INDEX(BAZA_PART,MATCH($C10,BAZA_EX,0)),"")} | N10: {=IFERROR(INDEX(BAZA_KAT,MATCH($C10,BAZA_EX,0)),"")} | O10: {=IFERROR(INDEX(BAZA_COEFF,MATCH($C10,BAZA_EX,0)),"")} | P10: {=IFERROR(INDEX(BAZA_SKOK,MATCH($C10,BAZA_EX,0)),"")} | Q10: {=IFERROR(INDEX(BAZA_PROG,MATCH($C10,BAZA_EX,0)),"")} | R10: =IF($C10="","",IF(SUMPRODUCT((START!$B$6:$B$69=$C10)*(START!$M$6:$M$69>0))=0,"",SUMPRODUCT(MAX((START!$B$6:$B$69=$C10)*START!$M$6:$M$69)))) | S10: {=IFERROR(INDEX(TABELE!$B$4:$J$18,MATCH($E10,TABELE!$A$4:$A$18,0),MATCH($F10,TABELE!$B$3:$J$3,0)),"")} | T10: {=IFERROR(IF($C10="",0,$O10*$D10*INDEX(TABELE!$B$23:$P$33,MATCH($F10,TABELE!$A$23:$A$33,0),MATCH($E10,TABELE!$B$22:$P$22,0))),0)} -> 0 | U10: {=IFERROR(IF($C10="",0,$O10*$D10*INDEX(TABELE!$B$37:$P$47,MATCH($F10,TABELE!$A$37:$A$47,0),MATCH($E10,TABELE!$B$36:$P$36,0))),0)} -> 0 | V10: {=IFERROR(IF($C10="",0,$O10*$D10*INDEX(TABELE!$B$51:$P$61,MATCH($F10,TABELE!$A$51:$A$61,0),MATCH($E10,TABELE!$B$50:$P$50,0))),0)} -> 0 | W10: {=IFERROR(INDEX(BAZA_UWAGI,MATCH($C10,BAZA_EX,0)),"")} | X10: =IF($A10="","",$Z10) -> 3 | Y10: =IF($A10="",$Y9,LEFT($A10,1)) -> C | Z10: =IF($A10="",$Z9,IF(LEFT($A10,1)=$Y9,$Z9,$Z9+1)) -> 3 | AB10: =IF($C10="","",IF($H10<>"",$H10,IF($H$19="✓ ukończony","OK",""))) | AC10: 1 | AD10: =IF(OR($Q10="masa ciała",$Q10="czas",$Q10="dystans",$Q10="ręczne ustawienie"),MAX(-3,MIN(3,ROUND(($AC10-1)/0.05,0))),0) -> 0
A11: C2. | D11: 3 | E11: =IF($C11="",0,MIN(15,MAX(1,IF(N($O11)>=1,6,IF(N($O11)>=0.75,IF(PRZEL_CZESC="część 1 (objętość)",8,6),IF(PRZEL_CZESC="część 1 (objętość)",10,8)))+0+$AD11))) -> 0 | F11: 9 | G11: =IF($C11="","",IF(OR($Q11="masa ciała",$Q11="czas",$Q11="dystans",$Q11="ręczne ustawienie"),$Q11,IF(OR($R11="",$R11=0),"— brak 1RM",MROUND($R11*$S11/100,MAX($P11,0.5))))) | I11: {=IFERROR(IF(IFERROR(INDEX(BAZA_FILM,MATCH($C11,BAZA_EX,0)),"")="","",HYPERLINK(IFERROR(INDEX(BAZA_FILM,MATCH($C11,BAZA_EX,0)),""),"film")),"")} | K11: D1-S05 | L11: {=IFERROR(INDEX(BAZA_ID,MATCH($C11,BAZA_EX,0)),"")} | M11: {=IFERROR(INDEX(BAZA_PART,MATCH($C11,BAZA_EX,0)),"")} | N11: {=IFERROR(INDEX(BAZA_KAT,MATCH($C11,BAZA_EX,0)),"")} | O11: {=IFERROR(INDEX(BAZA_COEFF,MATCH($C11,BAZA_EX,0)),"")} | P11: {=IFERROR(INDEX(BAZA_SKOK,MATCH($C11,BAZA_EX,0)),"")} | Q11: {=IFERROR(INDEX(BAZA_PROG,MATCH($C11,BAZA_EX,0)),"")} | R11: =IF($C11="","",IF(SUMPRODUCT((START!$B$6:$B$69=$C11)*(START!$M$6:$M$69>0))=0,"",SUMPRODUCT(MAX((START!$B$6:$B$69=$C11)*START!$M$6:$M$69)))) | S11: {=IFERROR(INDEX(TABELE!$B$4:$J$18,MATCH($E11,TABELE!$A$4:$A$18,0),MATCH($F11,TABELE!$B$3:$J$3,0)),"")} | T11: {=IFERROR(IF($C11="",0,$O11*$D11*INDEX(TABELE!$B$23:$P$33,MATCH($F11,TABELE!$A$23:$A$33,0),MATCH($E11,TABELE!$B$22:$P$22,0))),0)} -> 0 | U11: {=IFERROR(IF($C11="",0,$O11*$D11*INDEX(TABELE!$B$37:$P$47,MATCH($F11,TABELE!$A$37:$A$47,0),MATCH($E11,TABELE!$B$36:$P$36,0))),0)} -> 0 | V11: {=IFERROR(IF($C11="",0,$O11*$D11*INDEX(TABELE!$B$51:$P$61,MATCH($F11,TABELE!$A$51:$A$61,0),MATCH($E11,TABELE!$B$50:$P$50,0))),0)} -> 0 | W11: {=IFERROR(INDEX(BAZA_UWAGI,MATCH($C11,BAZA_EX,0)),"")} | X11: =IF($A11="","",$Z11) -> 3 | Y11: =IF($A11="",$Y10,LEFT($A11,1)) -> C | Z11: =IF($A11="",$Z10,IF(LEFT($A11,1)=$Y10,$Z10,$Z10+1)) -> 3 | AB11: =IF($C11="","",IF($H11<>"",$H11,IF($H$19="✓ ukończony","OK",""))) | AC11: 1 | AD11: =IF(OR($Q11="masa ciała",$Q11="czas",$Q11="dystans",$Q11="ręczne ustawienie"),MAX(-3,MIN(3,ROUND(($AC11-1)/0.05,0))),0) -> 0
A12: D1. | D12: 3 | E12: =IF($C12="",0,MIN(15,MAX(1,IF(N($O12)>=1,6,IF(N($O12)>=0.75,IF(PRZEL_CZESC="część 1 (objętość)",8,6),IF(PRZEL_CZESC="część 1 (objętość)",10,8)))+0+$AD12))) -> 0 | F12: 8 | G12: =IF($C12="","",IF(OR($Q12="masa ciała",$Q12="czas",$Q12="dystans",$Q12="ręczne ustawienie"),$Q12,IF(OR($R12="",$R12=0),"— brak 1RM",MROUND($R12*$S12/100,MAX($P12,0.5))))) | I12: {=IFERROR(IF(IFERROR(INDEX(BAZA_FILM,MATCH($C12,BAZA_EX,0)),"")="","",HYPERLINK(IFERROR(INDEX(BAZA_FILM,MATCH($C12,BAZA_EX,0)),""),"film")),"")} | K12: D1-S06 | L12: {=IFERROR(INDEX(BAZA_ID,MATCH($C12,BAZA_EX,0)),"")} | M12: {=IFERROR(INDEX(BAZA_PART,MATCH($C12,BAZA_EX,0)),"")} | N12: {=IFERROR(INDEX(BAZA_KAT,MATCH($C12,BAZA_EX,0)),"")} | O12: {=IFERROR(INDEX(BAZA_COEFF,MATCH($C12,BAZA_EX,0)),"")} | P12: {=IFERROR(INDEX(BAZA_SKOK,MATCH($C12,BAZA_EX,0)),"")} | Q12: {=IFERROR(INDEX(BAZA_PROG,MATCH($C12,BAZA_EX,0)),"")} | R12: =IF($C12="","",IF(SUMPRODUCT((START!$B$6:$B$69=$C12)*(START!$M$6:$M$69>0))=0,"",SUMPRODUCT(MAX((START!$B$6:$B$69=$C12)*START!$M$6:$M$69)))) | S12: {=IFERROR(INDEX(TABELE!$B$4:$J$18,MATCH($E12,TABELE!$A$4:$A$18,0),MATCH($F12,TABELE!$B$3:$J$3,0)),"")} | T12: {=IFERROR(IF($C12="",0,$O12*$D12*INDEX(TABELE!$B$23:$P$33,MATCH($F12,TABELE!$A$23:$A$33,0),MATCH($E12,TABELE!$B$22:$P$22,0))),0)} -> 0 | U12: {=IFERROR(IF($C12="",0,$O12*$D12*INDEX(TABELE!$B$37:$P$47,MATCH($F12,TABELE!$A$37:$A$47,0),MATCH($E12,TABELE!$B$36:$P$36,0))),0)} -> 0 | V12: {=IFERROR(IF($C12="",0,$O12*$D12*INDEX(TABELE!$B$51:$P$61,MATCH($F12,TABELE!$A$51:$A$61,0),MATCH($E12,TABELE!$B$50:$P$50,0))),0)} -> 0 | W12: {=IFERROR(INDEX(BAZA_UWAGI,MATCH($C12,BAZA_EX,0)),"")} | X12: =IF($A12="","",$Z12) -> 4 | Y12: =IF($A12="",$Y11,LEFT($A12,1)) -> D | Z12: =IF($A12="",$Z11,IF(LEFT($A12,1)=$Y11,$Z11,$Z11+1)) -> 4 | AB12: =IF($C12="","",IF($H12<>"",$H12,IF($H$19="✓ ukończony","OK",""))) | AC12: 1 | AD12: =IF(OR($Q12="masa ciała",$Q12="czas",$Q12="dystans",$Q12="ręczne ustawienie"),MAX(-3,MIN(3,ROUND(($AC12-1)/0.05,0))),0) -> 0
A13: D2. | D13: 3 | E13: =IF($C13="",0,MIN(15,MAX(1,IF(N($O13)>=1,6,IF(N($O13)>=0.75,IF(PRZEL_CZESC="część 1 (objętość)",8,6),IF(PRZEL_CZESC="część 1 (objętość)",10,8)))+0+$AD13))) -> 0 | F13: 9 | G13: =IF($C13="","",IF(OR($Q13="masa ciała",$Q13="czas",$Q13="dystans",$Q13="ręczne ustawienie"),$Q13,IF(OR($R13="",$R13=0),"— brak 1RM",MROUND($R13*$S13/100,MAX($P13,0.5))))) | I13: {=IFERROR(IF(IFERROR(INDEX(BAZA_FILM,MATCH($C13,BAZA_EX,0)),"")="","",HYPERLINK(IFERROR(INDEX(BAZA_FILM,MATCH($C13,BAZA_EX,0)),""),"film")),"")} | K13: D1-S07 | L13: {=IFERROR(INDEX(BAZA_ID,MATCH($C13,BAZA_EX,0)),"")} | M13: {=IFERROR(INDEX(BAZA_PART,MATCH($C13,BAZA_EX,0)),"")} | N13: {=IFERROR(INDEX(BAZA_KAT,MATCH($C13,BAZA_EX,0)),"")} | O13: {=IFERROR(INDEX(BAZA_COEFF,MATCH($C13,BAZA_EX,0)),"")} | P13: {=IFERROR(INDEX(BAZA_SKOK,MATCH($C13,BAZA_EX,0)),"")} | Q13: {=IFERROR(INDEX(BAZA_PROG,MATCH($C13,BAZA_EX,0)),"")} | R13: =IF($C13="","",IF(SUMPRODUCT((START!$B$6:$B$69=$C13)*(START!$M$6:$M$69>0))=0,"",SUMPRODUCT(MAX((START!$B$6:$B$69=$C13)*START!$M$6:$M$69)))) | S13: {=IFERROR(INDEX(TABELE!$B$4:$J$18,MATCH($E13,TABELE!$A$4:$A$18,0),MATCH($F13,TABELE!$B$3:$J$3,0)),"")} | T13: {=IFERROR(IF($C13="",0,$O13*$D13*INDEX(TABELE!$B$23:$P$33,MATCH($F13,TABELE!$A$23:$A$33,0),MATCH($E13,TABELE!$B$22:$P$22,0))),0)} -> 0 | U13: {=IFERROR(IF($C13="",0,$O13*$D13*INDEX(TABELE!$B$37:$P$47,MATCH($F13,TABELE!$A$37:$A$47,0),MATCH($E13,TABELE!$B$36:$P$36,0))),0)} -> 0 | V13: {=IFERROR(IF($C13="",0,$O13*$D13*INDEX(TABELE!$B$51:$P$61,MATCH($F13,TABELE!$A$51:$A$61,0),MATCH($E13,TABELE!$B$50:$P$50,0))),0)} -> 0 | W13: {=IFERROR(INDEX(BAZA_UWAGI,MATCH($C13,BAZA_EX,0)),"")} | X13: =IF($A13="","",$Z13) -> 4 | Y13: =IF($A13="",$Y12,LEFT($A13,1)) -> D | Z13: =IF($A13="",$Z12,IF(LEFT($A13,1)=$Y12,$Z12,$Z12+1)) -> 4 | AB13: =IF($C13="","",IF($H13<>"",$H13,IF($H$19="✓ ukończony","OK",""))) | AC13: 1 | AD13: =IF(OR($Q13="masa ciała",$Q13="czas",$Q13="dystans",$Q13="ręczne ustawienie"),MAX(-3,MIN(3,ROUND(($AC13-1)/0.05,0))),0) -> 0
A14: E1. | E14: =IF($C14="",0,MIN(15,MAX(1,IF(N($O14)>=1,6,IF(N($O14)>=0.75,IF(PRZEL_CZESC="część 1 (objętość)",8,6),IF(PRZEL_CZESC="część 1 (objętość)",10,8)))+0+$AD14))) -> 0 | G14: =IF($C14="","",IF(OR($Q14="masa ciała",$Q14="czas",$Q14="dystans",$Q14="ręczne ustawienie"),$Q14,IF(OR($R14="",$R14=0),"— brak 1RM",MROUND($R14*$S14/100,MAX($P14,0.5))))) | I14: {=IFERROR(IF(IFERROR(INDEX(BAZA_FILM,MATCH($C14,BAZA_EX,0)),"")="","",HYPERLINK(IFERROR(INDEX(BAZA_FILM,MATCH($C14,BAZA_EX,0)),""),"film")),"")} | K14: D1-S08 | L14: {=IFERROR(INDEX(BAZA_ID,MATCH($C14,BAZA_EX,0)),"")} | M14: {=IFERROR(INDEX(BAZA_PART,MATCH($C14,BAZA_EX,0)),"")} | N14: {=IFERROR(INDEX(BAZA_KAT,MATCH($C14,BAZA_EX,0)),"")} | O14: {=IFERROR(INDEX(BAZA_COEFF,MATCH($C14,BAZA_EX,0)),"")} | P14: {=IFERROR(INDEX(BAZA_SKOK,MATCH($C14,BAZA_EX,0)),"")} | Q14: {=IFERROR(INDEX(BAZA_PROG,MATCH($C14,BAZA_EX,0)),"")} | R14: =IF($C14="","",IF(SUMPRODUCT((START!$B$6:$B$69=$C14)*(START!$M$6:$M$69>0))=0,"",SUMPRODUCT(MAX((START!$B$6:$B$69=$C14)*START!$M$6:$M$69)))) | S14: {=IFERROR(INDEX(TABELE!$B$4:$J$18,MATCH($E14,TABELE!$A$4:$A$18,0),MATCH($F14,TABELE!$B$3:$J$3,0)),"")} | T14: {=IFERROR(IF($C14="",0,$O14*$D14*INDEX(TABELE!$B$23:$P$33,MATCH($F14,TABELE!$A$23:$A$33,0),MATCH($E14,TABELE!$B$22:$P$22,0))),0)} -> 0 | U14: {=IFERROR(IF($C14="",0,$O14*$D14*INDEX(TABELE!$B$37:$P$47,MATCH($F14,TABELE!$A$37:$A$47,0),MATCH($E14,TABELE!$B$36:$P$36,0))),0)} -> 0 | V14: {=IFERROR(IF($C14="",0,$O14*$D14*INDEX(TABELE!$B$51:$P$61,MATCH($F14,TABELE!$A$51:$A$61,0),MATCH($E14,TABELE!$B$50:$P$50,0))),0)} -> 0 | W14: {=IFERROR(INDEX(BAZA_UWAGI,MATCH($C14,BAZA_EX,0)),"")} | X14: =IF($A14="","",$Z14) -> 5 | Y14: =IF($A14="",$Y13,LEFT($A14,1)) -> E | Z14: =IF($A14="",$Z13,IF(LEFT($A14,1)=$Y13,$Z13,$Z13+1)) -> 5 | AB14: =IF($C14="","",IF($H14<>"",$H14,IF($H$19="✓ ukończony","OK",""))) | AC14: 1 | AD14: =IF(OR($Q14="masa ciała",$Q14="czas",$Q14="dystans",$Q14="ręczne ustawienie"),MAX(-3,MIN(3,ROUND(($AC14-1)/0.05,0))),0) -> 0
A15: E2. | E15: =IF($C15="",0,MIN(15,MAX(1,IF(N($O15)>=1,6,IF(N($O15)>=0.75,IF(PRZEL_CZESC="część 1 (objętość)",8,6),IF(PRZEL_CZESC="część 1 (objętość)",10,8)))+0+$AD15))) -> 0 | G15: =IF($C15="","",IF(OR($Q15="masa ciała",$Q15="czas",$Q15="dystans",$Q15="ręczne ustawienie"),$Q15,IF(OR($R15="",$R15=0),"— brak 1RM",MROUND($R15*$S15/100,MAX($P15,0.5))))) | I15: {=IFERROR(IF(IFERROR(INDEX(BAZA_FILM,MATCH($C15,BAZA_EX,0)),"")="","",HYPERLINK(IFERROR(INDEX(BAZA_FILM,MATCH($C15,BAZA_EX,0)),""),"film")),"")} | K15: D1-S09 | L15: {=IFERROR(INDEX(BAZA_ID,MATCH($C15,BAZA_EX,0)),"")} | M15: {=IFERROR(INDEX(BAZA_PART,MATCH($C15,BAZA_EX,0)),"")} | N15: {=IFERROR(INDEX(BAZA_KAT,MATCH($C15,BAZA_EX,0)),"")} | O15: {=IFERROR(INDEX(BAZA_COEFF,MATCH($C15,BAZA_EX,0)),"")} | P15: {=IFERROR(INDEX(BAZA_SKOK,MATCH($C15,BAZA_EX,0)),"")} | Q15: {=IFERROR(INDEX(BAZA_PROG,MATCH($C15,BAZA_EX,0)),"")} | R15: =IF($C15="","",IF(SUMPRODUCT((START!$B$6:$B$69=$C15)*(START!$M$6:$M$69>0))=0,"",SUMPRODUCT(MAX((START!$B$6:$B$69=$C15)*START!$M$6:$M$69)))) | S15: {=IFERROR(INDEX(TABELE!$B$4:$J$18,MATCH($E15,TABELE!$A$4:$A$18,0),MATCH($F15,TABELE!$B$3:$J$3,0)),"")} | T15: {=IFERROR(IF($C15="",0,$O15*$D15*INDEX(TABELE!$B$23:$P$33,MATCH($F15,TABELE!$A$23:$A$33,0),MATCH($E15,TABELE!$B$22:$P$22,0))),0)} -> 0 | U15: {=IFERROR(IF($C15="",0,$O15*$D15*INDEX(TABELE!$B$37:$P$47,MATCH($F15,TABELE!$A$37:$A$47,0),MATCH($E15,TABELE!$B$36:$P$36,0))),0)} -> 0 | V15: {=IFERROR(IF($C15="",0,$O15*$D15*INDEX(TABELE!$B$51:$P$61,MATCH($F15,TABELE!$A$51:$A$61,0),MATCH($E15,TABELE!$B$50:$P$50,0))),0)} -> 0 | W15: {=IFERROR(INDEX(BAZA_UWAGI,MATCH($C15,BAZA_EX,0)),"")} | X15: =IF($A15="","",$Z15) -> 5 | Y15: =IF($A15="",$Y14,LEFT($A15,1)) -> E | Z15: =IF($A15="",$Z14,IF(LEFT($A15,1)=$Y14,$Z14,$Z14+1)) -> 5 | AB15: =IF($C15="","",IF($H15<>"",$H15,IF($H$19="✓ ukończony","OK",""))) | AC15: 1 | AD15: =IF(OR($Q15="masa ciała",$Q15="czas",$Q15="dystans",$Q15="ręczne ustawienie"),MAX(-3,MIN(3,ROUND(($AC15-1)/0.05,0))),0) -> 0
E16: =IF($C16="",0,MIN(15,MAX(1,IF(N($O16)>=1,6,IF(N($O16)>=0.75,IF(PRZEL_CZESC="część 1 (objętość)",8,6),IF(PRZEL_CZESC="część 1 (objętość)",10,8)))+0+$AD16))) -> 0 | G16: =IF($C16="","",IF(OR($Q16="masa ciała",$Q16="czas",$Q16="dystans",$Q16="ręczne ustawienie"),$Q16,IF(OR($R16="",$R16=0),"— brak 1RM",MROUND($R16*$S16/100,MAX($P16,0.5))))) | I16: {=IFERROR(IF(IFERROR(INDEX(BAZA_FILM,MATCH($C16,BAZA_EX,0)),"")="","",HYPERLINK(IFERROR(INDEX(BAZA_FILM,MATCH($C16,BAZA_EX,0)),""),"film")),"")} | K16: D1-S10 | L16: {=IFERROR(INDEX(BAZA_ID,MATCH($C16,BAZA_EX,0)),"")} | M16: {=IFERROR(INDEX(BAZA_PART,MATCH($C16,BAZA_EX,0)),"")} | N16: {=IFERROR(INDEX(BAZA_KAT,MATCH($C16,BAZA_EX,0)),"")} | O16: {=IFERROR(INDEX(BAZA_COEFF,MATCH($C16,BAZA_EX,0)),"")} | P16: {=IFERROR(INDEX(BAZA_SKOK,MATCH($C16,BAZA_EX,0)),"")} | Q16: {=IFERROR(INDEX(BAZA_PROG,MATCH($C16,BAZA_EX,0)),"")} | R16: =IF($C16="","",IF(SUMPRODUCT((START!$B$6:$B$69=$C16)*(START!$M$6:$M$69>0))=0,"",SUMPRODUCT(MAX((START!$B$6:$B$69=$C16)*START!$M$6:$M$69)))) | S16: {=IFERROR(INDEX(TABELE!$B$4:$J$18,MATCH($E16,TABELE!$A$4:$A$18,0),MATCH($F16,TABELE!$B$3:$J$3,0)),"")} | T16: {=IFERROR(IF($C16="",0,$O16*$D16*INDEX(TABELE!$B$23:$P$33,MATCH($F16,TABELE!$A$23:$A$33,0),MATCH($E16,TABELE!$B$22:$P$22,0))),0)} -> 0 | U16: {=IFERROR(IF($C16="",0,$O16*$D16*INDEX(TABELE!$B$37:$P$47,MATCH($F16,TABELE!$A$37:$A$47,0),MATCH($E16,TABELE!$B$36:$P$36,0))),0)} -> 0 | V16: {=IFERROR(IF($C16="",0,$O16*$D16*INDEX(TABELE!$B$51:$P$61,MATCH($F16,TABELE!$A$51:$A$61,0),MATCH($E16,TABELE!$B$50:$P$50,0))),0)} -> 0 | W16: {=IFERROR(INDEX(BAZA_UWAGI,MATCH($C16,BAZA_EX,0)),"")} | X16: =IF($A16="","",$Z16) | Y16: =IF($A16="",$Y15,LEFT($A16,1)) -> E | Z16: =IF($A16="",$Z15,IF(LEFT($A16,1)=$Y15,$Z15,$Z15+1)) -> 5 | AB16: =IF($C16="","",IF($H16<>"",$H16,IF($H$19="✓ ukończony","OK",""))) | AC16: 1 | AD16: =IF(OR($Q16="masa ciała",$Q16="czas",$Q16="dystans",$Q16="ręczne ustawienie"),MAX(-3,MIN(3,ROUND(($AC16-1)/0.05,0))),0) -> 0
E17: =IF($C17="",0,MIN(15,MAX(1,IF(N($O17)>=1,6,IF(N($O17)>=0.75,IF(PRZEL_CZESC="część 1 (objętość)",8,6),IF(PRZEL_CZESC="część 1 (objętość)",10,8)))+0+$AD17))) -> 0 | G17: =IF($C17="","",IF(OR($Q17="masa ciała",$Q17="czas",$Q17="dystans",$Q17="ręczne ustawienie"),$Q17,IF(OR($R17="",$R17=0),"— brak 1RM",MROUND($R17*$S17/100,MAX($P17,0.5))))) | I17: {=IFERROR(IF(IFERROR(INDEX(BAZA_FILM,MATCH($C17,BAZA_EX,0)),"")="","",HYPERLINK(IFERROR(INDEX(BAZA_FILM,MATCH($C17,BAZA_EX,0)),""),"film")),"")} | K17: D1-S11 | L17: {=IFERROR(INDEX(BAZA_ID,MATCH($C17,BAZA_EX,0)),"")} | M17: {=IFERROR(INDEX(BAZA_PART,MATCH($C17,BAZA_EX,0)),"")} | N17: {=IFERROR(INDEX(BAZA_KAT,MATCH($C17,BAZA_EX,0)),"")} | O17: {=IFERROR(INDEX(BAZA_COEFF,MATCH($C17,BAZA_EX,0)),"")} | P17: {=IFERROR(INDEX(BAZA_SKOK,MATCH($C17,BAZA_EX,0)),"")} | Q17: {=IFERROR(INDEX(BAZA_PROG,MATCH($C17,BAZA_EX,0)),"")} | R17: =IF($C17="","",IF(SUMPRODUCT((START!$B$6:$B$69=$C17)*(START!$M$6:$M$69>0))=0,"",SUMPRODUCT(MAX((START!$B$6:$B$69=$C17)*START!$M$6:$M$69)))) | S17: {=IFERROR(INDEX(TABELE!$B$4:$J$18,MATCH($E17,TABELE!$A$4:$A$18,0),MATCH($F17,TABELE!$B$3:$J$3,0)),"")} | T17: {=IFERROR(IF($C17="",0,$O17*$D17*INDEX(TABELE!$B$23:$P$33,MATCH($F17,TABELE!$A$23:$A$33,0),MATCH($E17,TABELE!$B$22:$P$22,0))),0)} -> 0 | U17: {=IFERROR(IF($C17="",0,$O17*$D17*INDEX(TABELE!$B$37:$P$47,MATCH($F17,TABELE!$A$37:$A$47,0),MATCH($E17,TABELE!$B$36:$P$36,0))),0)} -> 0 | V17: {=IFERROR(IF($C17="",0,$O17*$D17*INDEX(TABELE!$B$51:$P$61,MATCH($F17,TABELE!$A$51:$A$61,0),MATCH($E17,TABELE!$B$50:$P$50,0))),0)} -> 0 | W17: {=IFERROR(INDEX(BAZA_UWAGI,MATCH($C17,BAZA_EX,0)),"")} | X17: =IF($A17="","",$Z17) | Y17: =IF($A17="",$Y16,LEFT($A17,1)) -> E | Z17: =IF($A17="",$Z16,IF(LEFT($A17,1)=$Y16,$Z16,$Z16+1)) -> 5 | AB17: =IF($C17="","",IF($H17<>"",$H17,IF($H$19="✓ ukończony","OK",""))) | AC17: 1 | AD17: =IF(OR($Q17="masa ciała",$Q17="czas",$Q17="dystans",$Q17="ręczne ustawienie"),MAX(-3,MIN(3,ROUND(($AC17-1)/0.05,0))),0) -> 0
E18: =IF($C18="",0,MIN(15,MAX(1,IF(N($O18)>=1,6,IF(N($O18)>=0.75,IF(PRZEL_CZESC="część 1 (objętość)",8,6),IF(PRZEL_CZESC="część 1 (objętość)",10,8)))+0+$AD18))) -> 0 | G18: =IF($C18="","",IF(OR($Q18="masa ciała",$Q18="czas",$Q18="dystans",$Q18="ręczne ustawienie"),$Q18,IF(OR($R18="",$R18=0),"— brak 1RM",MROUND($R18*$S18/100,MAX($P18,0.5))))) | I18: {=IFERROR(IF(IFERROR(INDEX(BAZA_FILM,MATCH($C18,BAZA_EX,0)),"")="","",HYPERLINK(IFERROR(INDEX(BAZA_FILM,MATCH($C18,BAZA_EX,0)),""),"film")),"")} | K18: D1-S12 | L18: {=IFERROR(INDEX(BAZA_ID,MATCH($C18,BAZA_EX,0)),"")} | M18: {=IFERROR(INDEX(BAZA_PART,MATCH($C18,BAZA_EX,0)),"")} | N18: {=IFERROR(INDEX(BAZA_KAT,MATCH($C18,BAZA_EX,0)),"")} | O18: {=IFERROR(INDEX(BAZA_COEFF,MATCH($C18,BAZA_EX,0)),"")} | P18: {=IFERROR(INDEX(BAZA_SKOK,MATCH($C18,BAZA_EX,0)),"")} | Q18: {=IFERROR(INDEX(BAZA_PROG,MATCH($C18,BAZA_EX,0)),"")} | R18: =IF($C18="","",IF(SUMPRODUCT((START!$B$6:$B$69=$C18)*(START!$M$6:$M$69>0))=0,"",SUMPRODUCT(MAX((START!$B$6:$B$69=$C18)*START!$M$6:$M$69)))) | S18: {=IFERROR(INDEX(TABELE!$B$4:$J$18,MATCH($E18,TABELE!$A$4:$A$18,0),MATCH($F18,TABELE!$B$3:$J$3,0)),"")} | T18: {=IFERROR(IF($C18="",0,$O18*$D18*INDEX(TABELE!$B$23:$P$33,MATCH($F18,TABELE!$A$23:$A$33,0),MATCH($E18,TABELE!$B$22:$P$22,0))),0)} -> 0 | U18: {=IFERROR(IF($C18="",0,$O18*$D18*INDEX(TABELE!$B$37:$P$47,MATCH($F18,TABELE!$A$37:$A$47,0),MATCH($E18,TABELE!$B$36:$P$36,0))),0)} -> 0 | V18: {=IFERROR(IF($C18="",0,$O18*$D18*INDEX(TABELE!$B$51:$P$61,MATCH($F18,TABELE!$A$51:$A$61,0),MATCH($E18,TABELE!$B$50:$P$50,0))),0)} -> 0 | W18: {=IFERROR(INDEX(BAZA_UWAGI,MATCH($C18,BAZA_EX,0)),"")} | X18: =IF($A18="","",$Z18) | Y18: =IF($A18="",$Y17,LEFT($A18,1)) -> E | Z18: =IF($A18="",$Z17,IF(LEFT($A18,1)=$Y17,$Z17,$Z17+1)) -> 5 | AB18: =IF($C18="","",IF($H18<>"",$H18,IF($H$19="✓ ukończony","OK",""))) | AC18: 1 | AD18: =IF(OR($Q18="masa ciała",$Q18="czas",$Q18="dystans",$Q18="ręczne ustawienie"),MAX(-3,MIN(3,ROUND(($AC18-1)/0.05,0))),0) -> 0
C19: Dzień I — razem | D19: =SUMPRODUCT((C7:C18<>"")*D7:D18)+IF(AND($B$6="TOP SET",$C$6<>""),1,0) | E19: =SUMPRODUCT((C7:C18<>"")*D7:D18*E7:E18)&" powt." -> 30 powt. | G19: ="stres t "&TEXT(SUM(T7:T18),"0.0") -> stres t 1,1
A21: DZIEŃ II
A22: =IF($B22="TOP SET","▲","") -> ▲ | B22: TOP SET | C22: =IF(OR($B22<>"TOP SET",$F22=""),"",IF(N($K22)=0,"",IF(INDEX($C$23:$C$34,$K22)="","",INDEX($C$23:$C$34,$K22)))) | D22: =IF(AND($B22="TOP SET",$F22<>""),1,"") | E22: =IF(AND($B22="TOP SET",$F22<>""),"1 powtórzenie","") | F22: 7 | G22: {=IF($B22<>"TOP SET","",IF($C22="","",IF(OR($Q22="masa ciała",$Q22="czas",$Q22="dystans",$Q22="ręczne ustawienie"),"—",IF(OR($R22="",$R22=0),"— brak 1RM",MROUND($R22*IFERROR(INDEX(TABELE!$B$4:$J$18,MATCH(1,TABELE!$A$4:$A$18,0),MATCH($F22,TABELE!$B$3:$J$3,0)),0)/100,MAX($P22,0.5))))))} | K22: =IFERROR(MATCH("A*",$A$23:$A$34,0),0) | P22: =IF(N($K22)=0,"",INDEX($P$23:$P$34,$K22)) | Q22: =IF(N($K22)=0,"",INDEX($Q$23:$Q$34,$K22)) | R22: =IF(N($K22)=0,"",INDEX($R$23:$R$34,$K22))
A23: A1. | D23: 6 | E23: 6 | F23: 6.5 | G23: =IF($C23="","",IF(OR($Q23="masa ciała",$Q23="czas",$Q23="dystans",$Q23="ręczne ustawienie"),$Q23,IF(OR($R23="",$R23=0),"— brak 1RM",MROUND($R23*$S23/100,MAX($P23,0.5))))) | I23: {=IFERROR(IF(IFERROR(INDEX(BAZA_FILM,MATCH($C23,BAZA_EX,0)),"")="","",HYPERLINK(IFERROR(INDEX(BAZA_FILM,MATCH($C23,BAZA_EX,0)),""),"film")),"")} | K23: D2-S01 | L23: {=IFERROR(INDEX(BAZA_ID,MATCH($C23,BAZA_EX,0)),"")} | M23: {=IFERROR(INDEX(BAZA_PART,MATCH($C23,BAZA_EX,0)),"")} | N23: {=IFERROR(INDEX(BAZA_KAT,MATCH($C23,BAZA_EX,0)),"")} | O23: {=IFERROR(INDEX(BAZA_COEFF,MATCH($C23,BAZA_EX,0)),"")} | P23: {=IFERROR(INDEX(BAZA_SKOK,MATCH($C23,BAZA_EX,0)),"")} | Q23: {=IFERROR(INDEX(BAZA_PROG,MATCH($C23,BAZA_EX,0)),"")} | R23: =IF($C23="","",IF(SUMPRODUCT((START!$B$6:$B$69=$C23)*(START!$M$6:$M$69>0))=0,"",SUMPRODUCT(MAX((START!$B$6:$B$69=$C23)*START!$M$6:$M$69)))) | S23: {=IFERROR(INDEX(TABELE!$B$4:$J$18,MATCH($E23,TABELE!$A$4:$A$18,0),MATCH($F23,TABELE!$B$3:$J$3,0)),"")} -> 69.5 | T23: {=IFERROR(IF($C23="",0,$O23*$D23*INDEX(TABELE!$B$23:$P$33,MATCH($F23,TABELE!$A$23:$A$33,0),MATCH($E23,TABELE!$B$22:$P$22,0))),0)} -> 0 | U23: {=IFERROR(IF($C23="",0,$O23*$D23*INDEX(TABELE!$B$37:$P$47,MATCH($F23,TABELE!$A$37:$A$47,0),MATCH($E23,TABELE!$B$36:$P$36,0))),0)} -> 0 | V23: {=IFERROR(IF($C23="",0,$O23*$D23*INDEX(TABELE!$B$51:$P$61,MATCH($F23,TABELE!$A$51:$A$61,0),MATCH($E23,TABELE!$B$50:$P$50,0))),0)} -> 0 | W23: {=IFERROR(INDEX(BAZA_UWAGI,MATCH($C23,BAZA_EX,0)),"")} | X23: =IF($A23="","",$Z23) -> 1 | Y23: =IF($A23="","",LEFT($A23,1)) -> A | Z23: =IF($A23="",0,1) -> 1 | AB23: =IF($C23="","",IF($H23<>"",$H23,IF($H$35="✓ ukończony","OK",""))) | AC23: 1 | AD23: =IF(OR($Q23="masa ciała",$Q23="czas",$Q23="dystans",$Q23="ręczne ustawienie"),MAX(-3,MIN(3,ROUND(($AC23-1)/0.05,0))),0) -> 0
A24: B1. | D24: 3 | E24: =IF($C24="",0,MIN(15,MAX(1,IF(N($O24)>=1,6,IF(N($O24)>=0.75,IF(PRZEL_CZESC="część 1 (objętość)",8,6),IF(PRZEL_CZESC="część 1 (objętość)",10,8)))+0+$AD24))) -> 0 | F24: 8 | G24: =IF($C24="","",IF(OR($Q24="masa ciała",$Q24="czas",$Q24="dystans",$Q24="ręczne ustawienie"),$Q24,IF(OR($R24="",$R24=0),"— brak 1RM",MROUND($R24*$S24/100,MAX($P24,0.5))))) | I24: {=IFERROR(IF(IFERROR(INDEX(BAZA_FILM,MATCH($C24,BAZA_EX,0)),"")="","",HYPERLINK(IFERROR(INDEX(BAZA_FILM,MATCH($C24,BAZA_EX,0)),""),"film")),"")} | K24: D2-S02 | L24: {=IFERROR(INDEX(BAZA_ID,MATCH($C24,BAZA_EX,0)),"")} | M24: {=IFERROR(INDEX(BAZA_PART,MATCH($C24,BAZA_EX,0)),"")} | N24: {=IFERROR(INDEX(BAZA_KAT,MATCH($C24,BAZA_EX,0)),"")} | O24: {=IFERROR(INDEX(BAZA_COEFF,MATCH($C24,BAZA_EX,0)),"")} | P24: {=IFERROR(INDEX(BAZA_SKOK,MATCH($C24,BAZA_EX,0)),"")} | Q24: {=IFERROR(INDEX(BAZA_PROG,MATCH($C24,BAZA_EX,0)),"")} | R24: =IF($C24="","",IF(SUMPRODUCT((START!$B$6:$B$69=$C24)*(START!$M$6:$M$69>0))=0,"",SUMPRODUCT(MAX((START!$B$6:$B$69=$C24)*START!$M$6:$M$69)))) | S24: {=IFERROR(INDEX(TABELE!$B$4:$J$18,MATCH($E24,TABELE!$A$4:$A$18,0),MATCH($F24,TABELE!$B$3:$J$3,0)),"")} | T24: {=IFERROR(IF($C24="",0,$O24*$D24*INDEX(TABELE!$B$23:$P$33,MATCH($F24,TABELE!$A$23:$A$33,0),MATCH($E24,TABELE!$B$22:$P$22,0))),0)} -> 0 | U24: {=IFERROR(IF($C24="",0,$O24*$D24*INDEX(TABELE!$B$37:$P$47,MATCH($F24,TABELE!$A$37:$A$47,0),MATCH($E24,TABELE!$B$36:$P$36,0))),0)} -> 0 | V24: {=IFERROR(IF($C24="",0,$O24*$D24*INDEX(TABELE!$B$51:$P$61,MATCH($F24,TABELE!$A$51:$A$61,0),MATCH($E24,TABELE!$B$50:$P$50,0))),0)} -> 0 | W24: {=IFERROR(INDEX(BAZA_UWAGI,MATCH($C24,BAZA_EX,0)),"")} | X24: =IF($A24="","",$Z24) -> 2 | Y24: =IF($A24="",$Y23,LEFT($A24,1)) -> B | Z24: =IF($A24="",$Z23,IF(LEFT($A24,1)=$Y23,$Z23,$Z23+1)) -> 2 | AB24: =IF($C24="","",IF($H24<>"",$H24,IF($H$35="✓ ukończony","OK",""))) | AC24: 1 | AD24: =IF(OR($Q24="masa ciała",$Q24="czas",$Q24="dystans",$Q24="ręczne ustawienie"),MAX(-3,MIN(3,ROUND(($AC24-1)/0.05,0))),0) -> 0
A25: B2. | D25: 3 | E25: =IF($C25="",0,MIN(15,MAX(1,IF(N($O25)>=1,6,IF(N($O25)>=0.75,IF(PRZEL_CZESC="część 1 (objętość)",8,6),IF(PRZEL_CZESC="część 1 (objętość)",10,8)))+0+$AD25))) -> 0 | F25: 8 | G25: =IF($C25="","",IF(OR($Q25="masa ciała",$Q25="czas",$Q25="dystans",$Q25="ręczne ustawienie"),$Q25,IF(OR($R25="",$R25=0),"— brak 1RM",MROUND($R25*$S25/100,MAX($P25,0.5))))) | I25: {=IFERROR(IF(IFERROR(INDEX(BAZA_FILM,MATCH($C25,BAZA_EX,0)),"")="","",HYPERLINK(IFERROR(INDEX(BAZA_FILM,MATCH($C25,BAZA_EX,0)),""),"film")),"")} | K25: D2-S03 | L25: {=IFERROR(INDEX(BAZA_ID,MATCH($C25,BAZA_EX,0)),"")} | M25: {=IFERROR(INDEX(BAZA_PART,MATCH($C25,BAZA_EX,0)),"")} | N25: {=IFERROR(INDEX(BAZA_KAT,MATCH($C25,BAZA_EX,0)),"")} | O25: {=IFERROR(INDEX(BAZA_COEFF,MATCH($C25,BAZA_EX,0)),"")} | P25: {=IFERROR(INDEX(BAZA_SKOK,MATCH($C25,BAZA_EX,0)),"")} | Q25: {=IFERROR(INDEX(BAZA_PROG,MATCH($C25,BAZA_EX,0)),"")} | R25: =IF($C25="","",IF(SUMPRODUCT((START!$B$6:$B$69=$C25)*(START!$M$6:$M$69>0))=0,"",SUMPRODUCT(MAX((START!$B$6:$B$69=$C25)*START!$M$6:$M$69)))) | S25: {=IFERROR(INDEX(TABELE!$B$4:$J$18,MATCH($E25,TABELE!$A$4:$A$18,0),MATCH($F25,TABELE!$B$3:$J$3,0)),"")} | T25: {=IFERROR(IF($C25="",0,$O25*$D25*INDEX(TABELE!$B$23:$P$33,MATCH($F25,TABELE!$A$23:$A$33,0),MATCH($E25,TABELE!$B$22:$P$22,0))),0)} -> 0 | U25: {=IFERROR(IF($C25="",0,$O25*$D25*INDEX(TABELE!$B$37:$P$47,MATCH($F25,TABELE!$A$37:$A$47,0),MATCH($E25,TABELE!$B$36:$P$36,0))),0)} -> 0 | V25: {=IFERROR(IF($C25="",0,$O25*$D25*INDEX(TABELE!$B$51:$P$61,MATCH($F25,TABELE!$A$51:$A$61,0),MATCH($E25,TABELE!$B$50:$P$50,0))),0)} -> 0 | W25: {=IFERROR(INDEX(BAZA_UWAGI,MATCH($C25,BAZA_EX,0)),"")} | X25: =IF($A25="","",$Z25) -> 2 | Y25: =IF($A25="",$Y24,LEFT($A25,1)) -> B | Z25: =IF($A25="",$Z24,IF(LEFT($A25,1)=$Y24,$Z24,$Z24+1)) -> 2 | AB25: =IF($C25="","",IF($H25<>"",$H25,IF($H$35="✓ ukończony","OK",""))) | AC25: 1 | AD25: =IF(OR($Q25="masa ciała",$Q25="czas",$Q25="dystans",$Q25="ręczne ustawienie"),MAX(-3,MIN(3,ROUND(($AC25-1)/0.05,0))),0) -> 0
A26: C1. | D26: 3 | E26: =IF($C26="",0,MIN(15,MAX(1,IF(N($O26)>=1,6,IF(N($O26)>=0.75,IF(PRZEL_CZESC="część 1 (objętość)",8,6),IF(PRZEL_CZESC="część 1 (objętość)",10,8)))+0+$AD26))) -> 0 | F26: 8 | G26: =IF($C26="","",IF(OR($Q26="masa ciała",$Q26="czas",$Q26="dystans",$Q26="ręczne ustawienie"),$Q26,IF(OR($R26="",$R26=0),"— brak 1RM",MROUND($R26*$S26/100,MAX($P26,0.5))))) | I26: {=IFERROR(IF(IFERROR(INDEX(BAZA_FILM,MATCH($C26,BAZA_EX,0)),"")="","",HYPERLINK(IFERROR(INDEX(BAZA_FILM,MATCH($C26,BAZA_EX,0)),""),"film")),"")} | K26: D2-S04 | L26: {=IFERROR(INDEX(BAZA_ID,MATCH($C26,BAZA_EX,0)),"")} | M26: {=IFERROR(INDEX(BAZA_PART,MATCH($C26,BAZA_EX,0)),"")} | N26: {=IFERROR(INDEX(BAZA_KAT,MATCH($C26,BAZA_EX,0)),"")} | O26: {=IFERROR(INDEX(BAZA_COEFF,MATCH($C26,BAZA_EX,0)),"")} | P26: {=IFERROR(INDEX(BAZA_SKOK,MATCH($C26,BAZA_EX,0)),"")} | Q26: {=IFERROR(INDEX(BAZA_PROG,MATCH($C26,BAZA_EX,0)),"")} | R26: =IF($C26="","",IF(SUMPRODUCT((START!$B$6:$B$69=$C26)*(START!$M$6:$M$69>0))=0,"",SUMPRODUCT(MAX((START!$B$6:$B$69=$C26)*START!$M$6:$M$69)))) | S26: {=IFERROR(INDEX(TABELE!$B$4:$J$18,MATCH($E26,TABELE!$A$4:$A$18,0),MATCH($F26,TABELE!$B$3:$J$3,0)),"")} | T26: {=IFERROR(IF($C26="",0,$O26*$D26*INDEX(TABELE!$B$23:$P$33,MATCH($F26,TABELE!$A$23:$A$33,0),MATCH($E26,TABELE!$B$22:$P$22,0))),0)} -> 0 | U26: {=IFERROR(IF($C26="",0,$O26*$D26*INDEX(TABELE!$B$37:$P$47,MATCH($F26,TABELE!$A$37:$A$47,0),MATCH($E26,TABELE!$B$36:$P$36,0))),0)} -> 0 | V26: {=IFERROR(IF($C26="",0,$O26*$D26*INDEX(TABELE!$B$51:$P$61,MATCH($F26,TABELE!$A$51:$A$61,0),MATCH($E26,TABELE!$B$50:$P$50,0))),0)} -> 0 | W26: {=IFERROR(INDEX(BAZA_UWAGI,MATCH($C26,BAZA_EX,0)),"")} | X26: =IF($A26="","",$Z26) -> 3 | Y26: =IF($A26="",$Y25,LEFT($A26,1)) -> C | Z26: =IF($A26="",$Z25,IF(LEFT($A26,1)=$Y25,$Z25,$Z25+1)) -> 3 | AB26: =IF($C26="","",IF($H26<>"",$H26,IF($H$35="✓ ukończony","OK",""))) | AC26: 1 | AD26: =IF(OR($Q26="masa ciała",$Q26="czas",$Q26="dystans",$Q26="ręczne ustawienie"),MAX(-3,MIN(3,ROUND(($AC26-1)/0.05,0))),0) -> 0
A27: C2. | D27: 3 | E27: =IF($C27="",0,MIN(15,MAX(1,IF(N($O27)>=1,6,IF(N($O27)>=0.75,IF(PRZEL_CZESC="część 1 (objętość)",8,6),IF(PRZEL_CZESC="część 1 (objętość)",10,8)))+0+$AD27))) -> 0 | F27: 9 | G27: =IF($C27="","",IF(OR($Q27="masa ciała",$Q27="czas",$Q27="dystans",$Q27="ręczne ustawienie"),$Q27,IF(OR($R27="",$R27=0),"— brak 1RM",MROUND($R27*$S27/100,MAX($P27,0.5))))) | I27: {=IFERROR(IF(IFERROR(INDEX(BAZA_FILM,MATCH($C27,BAZA_EX,0)),"")="","",HYPERLINK(IFERROR(INDEX(BAZA_FILM,MATCH($C27,BAZA_EX,0)),""),"film")),"")} | K27: D2-S05 | L27: {=IFERROR(INDEX(BAZA_ID,MATCH($C27,BAZA_EX,0)),"")} | M27: {=IFERROR(INDEX(BAZA_PART,MATCH($C27,BAZA_EX,0)),"")} | N27: {=IFERROR(INDEX(BAZA_KAT,MATCH($C27,BAZA_EX,0)),"")} | O27: {=IFERROR(INDEX(BAZA_COEFF,MATCH($C27,BAZA_EX,0)),"")} | P27: {=IFERROR(INDEX(BAZA_SKOK,MATCH($C27,BAZA_EX,0)),"")} | Q27: {=IFERROR(INDEX(BAZA_PROG,MATCH($C27,BAZA_EX,0)),"")} | R27: =IF($C27="","",IF(SUMPRODUCT((START!$B$6:$B$69=$C27)*(START!$M$6:$M$69>0))=0,"",SUMPRODUCT(MAX((START!$B$6:$B$69=$C27)*START!$M$6:$M$69)))) | S27: {=IFERROR(INDEX(TABELE!$B$4:$J$18,MATCH($E27,TABELE!$A$4:$A$18,0),MATCH($F27,TABELE!$B$3:$J$3,0)),"")} | T27: {=IFERROR(IF($C27="",0,$O27*$D27*INDEX(TABELE!$B$23:$P$33,MATCH($F27,TABELE!$A$23:$A$33,0),MATCH($E27,TABELE!$B$22:$P$22,0))),0)} -> 0 | U27: {=IFERROR(IF($C27="",0,$O27*$D27*INDEX(TABELE!$B$37:$P$47,MATCH($F27,TABELE!$A$37:$A$47,0),MATCH($E27,TABELE!$B$36:$P$36,0))),0)} -> 0 | V27: {=IFERROR(IF($C27="",0,$O27*$D27*INDEX(TABELE!$B$51:$P$61,MATCH($F27,TABELE!$A$51:$A$61,0),MATCH($E27,TABELE!$B$50:$P$50,0))),0)} -> 0 | W27: {=IFERROR(INDEX(BAZA_UWAGI,MATCH($C27,BAZA_EX,0)),"")} | X27: =IF($A27="","",$Z27) -> 3 | Y27: =IF($A27="",$Y26,LEFT($A27,1)) -> C | Z27: =IF($A27="",$Z26,IF(LEFT($A27,1)=$Y26,$Z26,$Z26+1)) -> 3 | AB27: =IF($C27="","",IF($H27<>"",$H27,IF($H$35="✓ ukończony","OK",""))) | AC27: 1 | AD27: =IF(OR($Q27="masa ciała",$Q27="czas",$Q27="dystans",$Q27="ręczne ustawienie"),MAX(-3,MIN(3,ROUND(($AC27-1)/0.05,0))),0) -> 0
A28: D1. | D28: 3 | E28: =IF($C28="",0,MIN(15,MAX(1,IF(N($O28)>=1,6,IF(N($O28)>=0.75,IF(PRZEL_CZESC="część 1 (objętość)",8,6),IF(PRZEL_CZESC="część 1 (objętość)",10,8)))+0+$AD28))) -> 0 | F28: 8 | G28: =IF($C28="","",IF(OR($Q28="masa ciała",$Q28="czas",$Q28="dystans",$Q28="ręczne ustawienie"),$Q28,IF(OR($R28="",$R28=0),"— brak 1RM",MROUND($R28*$S28/100,MAX($P28,0.5))))) | I28: {=IFERROR(IF(IFERROR(INDEX(BAZA_FILM,MATCH($C28,BAZA_EX,0)),"")="","",HYPERLINK(IFERROR(INDEX(BAZA_FILM,MATCH($C28,BAZA_EX,0)),""),"film")),"")} | K28: D2-S06 | L28: {=IFERROR(INDEX(BAZA_ID,MATCH($C28,BAZA_EX,0)),"")} | M28: {=IFERROR(INDEX(BAZA_PART,MATCH($C28,BAZA_EX,0)),"")} | N28: {=IFERROR(INDEX(BAZA_KAT,MATCH($C28,BAZA_EX,0)),"")} | O28: {=IFERROR(INDEX(BAZA_COEFF,MATCH($C28,BAZA_EX,0)),"")} | P28: {=IFERROR(INDEX(BAZA_SKOK,MATCH($C28,BAZA_EX,0)),"")} | Q28: {=IFERROR(INDEX(BAZA_PROG,MATCH($C28,BAZA_EX,0)),"")} | R28: =IF($C28="","",IF(SUMPRODUCT((START!$B$6:$B$69=$C28)*(START!$M$6:$M$69>0))=0,"",SUMPRODUCT(MAX((START!$B$6:$B$69=$C28)*START!$M$6:$M$69)))) | S28: {=IFERROR(INDEX(TABELE!$B$4:$J$18,MATCH($E28,TABELE!$A$4:$A$18,0),MATCH($F28,TABELE!$B$3:$J$3,0)),"")} | T28: {=IFERROR(IF($C28="",0,$O28*$D28*INDEX(TABELE!$B$23:$P$33,MATCH($F28,TABELE!$A$23:$A$33,0),MATCH($E28,TABELE!$B$22:$P$22,0))),0)} -> 0 | U28: {=IFERROR(IF($C28="",0,$O28*$D28*INDEX(TABELE!$B$37:$P$47,MATCH($F28,TABELE!$A$37:$A$47,0),MATCH($E28,TABELE!$B$36:$P$36,0))),0)} -> 0 | V28: {=IFERROR(IF($C28="",0,$O28*$D28*INDEX(TABELE!$B$51:$P$61,MATCH($F28,TABELE!$A$51:$A$61,0),MATCH($E28,TABELE!$B$50:$P$50,0))),0)} -> 0 | W28: {=IFERROR(INDEX(BAZA_UWAGI,MATCH($C28,BAZA_EX,0)),"")} | X28: =IF($A28="","",$Z28) -> 4 | Y28: =IF($A28="",$Y27,LEFT($A28,1)) -> D | Z28: =IF($A28="",$Z27,IF(LEFT($A28,1)=$Y27,$Z27,$Z27+1)) -> 4 | AB28: =IF($C28="","",IF($H28<>"",$H28,IF($H$35="✓ ukończony","OK",""))) | AC28: 1 | AD28: =IF(OR($Q28="masa ciała",$Q28="czas",$Q28="dystans",$Q28="ręczne ustawienie"),MAX(-3,MIN(3,ROUND(($AC28-1)/0.05,0))),0) -> 0
A29: D2. | D29: 3 | E29: =IF($C29="",0,MIN(15,MAX(1,IF(N($O29)>=1,6,IF(N($O29)>=0.75,IF(PRZEL_CZESC="część 1 (objętość)",8,6),IF(PRZEL_CZESC="część 1 (objętość)",10,8)))+0+$AD29))) -> 0 | F29: 9 | G29: =IF($C29="","",IF(OR($Q29="masa ciała",$Q29="czas",$Q29="dystans",$Q29="ręczne ustawienie"),$Q29,IF(OR($R29="",$R29=0),"— brak 1RM",MROUND($R29*$S29/100,MAX($P29,0.5))))) | I29: {=IFERROR(IF(IFERROR(INDEX(BAZA_FILM,MATCH($C29,BAZA_EX,0)),"")="","",HYPERLINK(IFERROR(INDEX(BAZA_FILM,MATCH($C29,BAZA_EX,0)),""),"film")),"")} | K29: D2-S07 | L29: {=IFERROR(INDEX(BAZA_ID,MATCH($C29,BAZA_EX,0)),"")} | M29: {=IFERROR(INDEX(BAZA_PART,MATCH($C29,BAZA_EX,0)),"")} | N29: {=IFERROR(INDEX(BAZA_KAT,MATCH($C29,BAZA_EX,0)),"")} | O29: {=IFERROR(INDEX(BAZA_COEFF,MATCH($C29,BAZA_EX,0)),"")} | P29: {=IFERROR(INDEX(BAZA_SKOK,MATCH($C29,BAZA_EX,0)),"")} | Q29: {=IFERROR(INDEX(BAZA_PROG,MATCH($C29,BAZA_EX,0)),"")} | R29: =IF($C29="","",IF(SUMPRODUCT((START!$B$6:$B$69=$C29)*(START!$M$6:$M$69>0))=0,"",SUMPRODUCT(MAX((START!$B$6:$B$69=$C29)*START!$M$6:$M$69)))) | S29: {=IFERROR(INDEX(TABELE!$B$4:$J$18,MATCH($E29,TABELE!$A$4:$A$18,0),MATCH($F29,TABELE!$B$3:$J$3,0)),"")} | T29: {=IFERROR(IF($C29="",0,$O29*$D29*INDEX(TABELE!$B$23:$P$33,MATCH($F29,TABELE!$A$23:$A$33,0),MATCH($E29,TABELE!$B$22:$P$22,0))),0)} -> 0 | U29: {=IFERROR(IF($C29="",0,$O29*$D29*INDEX(TABELE!$B$37:$P$47,MATCH($F29,TABELE!$A$37:$A$47,0),MATCH($E29,TABELE!$B$36:$P$36,0))),0)} -> 0 | V29: {=IFERROR(IF($C29="",0,$O29*$D29*INDEX(TABELE!$B$51:$P$61,MATCH($F29,TABELE!$A$51:$A$61,0),MATCH($E29,TABELE!$B$50:$P$50,0))),0)} -> 0 | W29: {=IFERROR(INDEX(BAZA_UWAGI,MATCH($C29,BAZA_EX,0)),"")} | X29: =IF($A29="","",$Z29) -> 4 | Y29: =IF($A29="",$Y28,LEFT($A29,1)) -> D | Z29: =IF($A29="",$Z28,IF(LEFT($A29,1)=$Y28,$Z28,$Z28+1)) -> 4 | AB29: =IF($C29="","",IF($H29<>"",$H29,IF($H$35="✓ ukończony","OK",""))) | AC29: 1 | AD29: =IF(OR($Q29="masa ciała",$Q29="czas",$Q29="dystans",$Q29="ręczne ustawienie"),MAX(-3,MIN(3,ROUND(($AC29-1)/0.05,0))),0) -> 0
A30: E1. | E30: =IF($C30="",0,MIN(15,MAX(1,IF(N($O30)>=1,6,IF(N($O30)>=0.75,IF(PRZEL_CZESC="część 1 (objętość)",8,6),IF(PRZEL_CZESC="część 1 (objętość)",10,8)))+0+$AD30))) -> 0 | G30: =IF($C30="","",IF(OR($Q30="masa ciała",$Q30="czas",$Q30="dystans",$Q30="ręczne ustawienie"),$Q30,IF(OR($R30="",$R30=0),"— brak 1RM",MROUND($R30*$S30/100,MAX($P30,0.5))))) | I30: {=IFERROR(IF(IFERROR(INDEX(BAZA_FILM,MATCH($C30,BAZA_EX,0)),"")="","",HYPERLINK(IFERROR(INDEX(BAZA_FILM,MATCH($C30,BAZA_EX,0)),""),"film")),"")} | K30: D2-S08 | L30: {=IFERROR(INDEX(BAZA_ID,MATCH($C30,BAZA_EX,0)),"")} | M30: {=IFERROR(INDEX(BAZA_PART,MATCH($C30,BAZA_EX,0)),"")} | N30: {=IFERROR(INDEX(BAZA_KAT,MATCH($C30,BAZA_EX,0)),"")} | O30: {=IFERROR(INDEX(BAZA_COEFF,MATCH($C30,BAZA_EX,0)),"")} | P30: {=IFERROR(INDEX(BAZA_SKOK,MATCH($C30,BAZA_EX,0)),"")} | Q30: {=IFERROR(INDEX(BAZA_PROG,MATCH($C30,BAZA_EX,0)),"")} | R30: =IF($C30="","",IF(SUMPRODUCT((START!$B$6:$B$69=$C30)*(START!$M$6:$M$69>0))=0,"",SUMPRODUCT(MAX((START!$B$6:$B$69=$C30)*START!$M$6:$M$69)))) | S30: {=IFERROR(INDEX(TABELE!$B$4:$J$18,MATCH($E30,TABELE!$A$4:$A$18,0),MATCH($F30,TABELE!$B$3:$J$3,0)),"")} | T30: {=IFERROR(IF($C30="",0,$O30*$D30*INDEX(TABELE!$B$23:$P$33,MATCH($F30,TABELE!$A$23:$A$33,0),MATCH($E30,TABELE!$B$22:$P$22,0))),0)} -> 0 | U30: {=IFERROR(IF($C30="",0,$O30*$D30*INDEX(TABELE!$B$37:$P$47,MATCH($F30,TABELE!$A$37:$A$47,0),MATCH($E30,TABELE!$B$36:$P$36,0))),0)} -> 0 | V30: {=IFERROR(IF($C30="",0,$O30*$D30*INDEX(TABELE!$B$51:$P$61,MATCH($F30,TABELE!$A$51:$A$61,0),MATCH($E30,TABELE!$B$50:$P$50,0))),0)} -> 0 | W30: {=IFERROR(INDEX(BAZA_UWAGI,MATCH($C30,BAZA_EX,0)),"")} | X30: =IF($A30="","",$Z30) -> 5 | Y30: =IF($A30="",$Y29,LEFT($A30,1)) -> E | Z30: =IF($A30="",$Z29,IF(LEFT($A30,1)=$Y29,$Z29,$Z29+1)) -> 5 | AB30: =IF($C30="","",IF($H30<>"",$H30,IF($H$35="✓ ukończony","OK",""))) | AC30: 1 | AD30: =IF(OR($Q30="masa ciała",$Q30="czas",$Q30="dystans",$Q30="ręczne ustawienie"),MAX(-3,MIN(3,ROUND(($AC30-1)/0.05,0))),0) -> 0
